Workbook

Sheet MoM-Growth
A1: month 2(current) | B1: month 1(last) | C1: (Month 2 - Month 1) / Month 1 * 100
A2: 1815975 | B2: 1452406 | C2: =SUM(A2-B2)/B2*100 -> 25.032188
A3: 148616 | B3: 127069 | C3: =SUM(A3-B3)/B3*100 -> 16.956929
A4: 1649903 | B4: 1281828 | C4: =SUM(A4-B4)/B4*100 -> 28.714851
A5: 1.74 | B5: 1.71 | C5: =SUM(A5-B5)/B5*100 -> 1.754386
A6: 0.0016319444 | B6: 0.0017361111 | C6: =SUM(A6-B6)/B6*100 -> -6
A7: 2306319 | B7: 1883860 | C7: =SUM(A7-B7)/B7*100 -> 22.42518
A8: 4009027 | B8: 3322431 | C8: =SUM(A8-B8)/B8*100 -> 20.665471
A9: 6252 | B9: 5807 | C9: =SUM(A9-B9)/B9*100 -> 7.6631651
A10: 34 | B10: 36 | C10: =SUM(A10-B10)/B10*100 -> -5.5555556

Sheet tbltransaction-organic
A1: Month | B1: Innova Crysta | C1: Camry | D1: Fortuner | E1: Legender | F1: Vellfire | G1: Innova Hycross | H1: Hilux | I1: Glanza | J1: Urban Cruiser Hyryder | K1: Urban Cruiser Taisor | L1: Land Cruiser 300 | M1: Rumion
A2: Apr 2025 | B2: 461 | C2: 197 | D2: 535 | E2: 238 | F2: 61 | G2: 1260 | H2: 195 | I2: 386 | J2: 1137 | K2: 495 | L2: 118 | M2: 250
A3: May 2025 | B3: 378 | C3: 191 | D3: 493 | E3: 233 | F3: 145 | G3: 1160 | H3: 178 | I3: 396 | J3: 1124 | K3: 433 | L3: 110 | M3: 236
A4: Jun 2025 | B4: 414 | C4: 185 | D4: 637 | E4: 245 | F4: 463 | G4: 1157 | H4: 170 | I4: 458 | J4: 1061 | K4: 439 | L4: 100 | M4: 236
A5: Jul 2025 | B5: 414 | C5: 220 | D5: 584 | E5: 257 | F5: 263 | G5: 1046 | H5: 180 | I5: 491 | J5: 1132 | K5: 466 | L5: 342 | M5: 217
A6: Aug 2025 | B6: 455 | C6: 187 | D6: 518 | E6: 247 | F6: 123 | G6: 1003 | H6: 205 | I6: 460 | J6: 1084 | K6: 477 | L6: 830 | M6: 218
A7: Sep 2025 | B7: 597 | C7: 175 | D7: 608 | E7: 278 | F7: 98 | G7: 1182 | H7: 241 | I7: 483 | J7: 1237 | K7: 721 | L7: 417 | M7: 215
A8: Oct 2025 | B8: 537 | C8: 162 | D8: 721 | E8: 269 | F8: 114 | G8: 1207 | H8: 175 | I8: 470 | J8: 1215 | K8: 580 | L8: 456 | M8: 274 | N8: =SUM(B8:M8) -> 6180
A9: Total(model-wise) | B9: =SUM(B2:B8) -> 3256 | C9: =SUM(C2:C8) -> 1317 | D9: =SUM(D2:D8) -> 4096 | E9: =SUM(E2:E8) -> 1767 | F9: =SUM(F2:F8) -> 1267 | G9: =SUM(G2:G8) -> 8015 | H9: =SUM(H2:H8) -> 1344 | I9: =SUM(I2:I8) -> 3144 | ... M9: =SUM(M2:M8) -> 1646

Sheet tbltransaction-paid
A1: Month | B1: Innova Crysta | C1: Camry | D1: Fortuner | E1: Legender | F1: Vellfire | G1: Innova Hycross | H1: Hilux | I1: Glanza | J1: Urban Cruiser Hyryder | K1: Urban Cruiser Taisor | L1: Land Cruiser 300 | M1: Rumion
A2: Apr 2025 | B2: 2238 | C2: 483 | D2: 2982 | E2: 10 | F2: 3 | G2: 80 | H2: 2597 | I2: 7364 | J2: 26545 | K2: 12177 | L2: 18 | M2: 9
A3: May 2025 | B3: 983 | C3: 4048 | D3: 21 | E3: 6 | F3: 675 | G3: 2198 | H3: 5243 | I3: 28472 | J3: 34930 | K3: 18748 | L3: 7 | M3: 12
A4: Jun 2025 | B4: 4415 | C4: 4524 | D4: 3049 | E4: 21 | F4: 2707 | G4: 3613 | H4: 5297 | I4: 32974 | J4: 33303 | K4: 18437 | L4: 11 | M4: 8
A5: Jul 2025 | B5: 32 | C5: 3130 | D5: 1739 | E5: 2882 | F5: 1433 | G5: 4913 | H5: 5337 | I5: 41708 | J5: 34248 | K5: 12111 | L5: 632 | M5: 8
A6: Aug 2025 | B6: 2415 | C6: 3616 | D6: 201 | E6: 2881 | F6: 2149 | G6: 4148 | H6: 6111 | I6: 37094 | J6: 45498 | K6: 15442 | L6: 1588 | M6: 13
A7: Sep 2025 | B7: 7723 | C7: 4662 | D7: 41 | E7: 4329 | F7: 2525 | G7: 5490 | H7: 5800 | I7: 40908 | J7: 51184 | K7: 18184 | L7: 1382 | M7: 10
A8: Oct 2025 | B8: 7823 | C8: 6338 | D8: 4060 | E8: 2935 | F8: 2377 | G8: 8670 | H8: 6878 | I8: 51964 | J8: 55585 | K8: 25208 | L8: 2022 | M8: 12
A9: Total (model-wise) | B9: =SUM(B2:B8) -> 25629 | C9: =SUM(C2:C8) -> 26801 | D9: =SUM(D2:D8) -> 12093 | E9: =SUM(E2:E8) -> 13064 | F9: =SUM(F2:F8) -> 11869 | G9: =SUM(G2:G8) -> 29112 | H9: =SUM(H2:H8) -> 37263 | I9: =SUM(I2:I8) -> 240484 | ... M9: =SUM(M2:M8) -> 72

Sheet users-and-bounce-rate
A1: Months | B1: 45658 | D1: 45689 | F1: 45717 | H1: 45748 | J1: 45778 | L1: 45809
A2: Device | B2: Desktop Users | C2: Mobile Users | D2: Desktop Users | E2: Mobile Users | F2: Desktop Users | G2: Mobile Users | H2: Desktop Users | I2: Mobile Users | J2: Desktop Users | K2: Mobile Users | L2: Desktop Users | M2: MobileUsers
A3: Users | B3: 0.2439 | C3: 0.6168 | D3: 0.2519 | E3: 0.5689 | F3: 0.2502 | G3: 0.5414 | H3: 0.2389 | I3: 0.5086 | J3: 0.2419 | K3: 0.4352 | L3: 0.2807 | M3: 0.5982
A4: Bounce Rate | B4: 0.2439 | C4: 0.6168 | D4: 0.2519 | E4: 0.5689 | F4: 0.2502 | G4: 0.5414 | H4: 0.2389 | I4: 0.5086 | J4: 0.2419 | K4: 0.4352 | L4: 0.2807 | M4: 0.5982

Sheet productsbouncerate
B1: Bounce Rate | C1: views | D1: Percentage | E1: Final output
A2: /showroom/camry/ | B2: 68.60% | C2: 435656 | D2: =C2/$I$4 -> 0.11019198 | E2: =TEXT(C2, "0") & CHAR(10) &"("& TEXT(D2, "0.00%")&")" -> 435656 (11.02%)
A3: /showroom/fortuner/index-fortuner.html | B3: 36.04% | C3: 169366 | D3: =C3/$I$4 -> 0.042838328 | E3: =TEXT(C3, "0") & CHAR(10) &"("& TEXT(D3, "0.00%")&")" -> 169366 (4.28%)
A4: /showroom/fortuner/index-legender.html | B4: 14.71% | C4: 42240 | D4: =C4/$I$4 -> 0.010683909 | E4: =TEXT(C4, "0") & CHAR(10) &"("& TEXT(D4, "0.00%")&")" -> 42240 (1.07%) | I4: ='Site - Month Graph'!D35 -> 3953609
A5: /showroom/glanza/ | B5: 41.69% | C5: 116117 | D5: =C5/$I$4 -> 0.029369874 | E5: =TEXT(C5, "0") & CHAR(10) &"("& TEXT(D5, "0.00%")&")" -> 116117 (2.94%)
A6: /showroom/hilux/ | B6: 18.30% | C6: 43786 | D6: =C6/$I$4 -> 0.011074944 | E6: =TEXT(C6, "0") & CHAR(10) &"("& TEXT(D6, "0.00%")&")" -> 43786 (1.11%)
A7: /showroom/innova/ | B7: 15.68% | C7: 135563 | D7: =C7/$I$4 -> 0.034288419 | E7: =TEXT(C7, "0") & CHAR(10) &"("& TEXT(D7, "0.00%")&")" -> 135563 (3.43%)
A8: /showroom/innova-crysta/ | B8: 21.86% | C8: 104335 | D8: =C8/$I$4 -> 0.026389812 | E8: =TEXT(C8, "0") & CHAR(10) &"("& TEXT(D8, "0.00%")&")" -> 104335 (2.64%)
A9: /showroom/lc300/ | B9: 21.62% | C9: 59918 | D9: =C9/$I$4 -> 0.015155267 | E9: =TEXT(C9, "0") & CHAR(10) &"("& TEXT(D9, "0.00%")&")" -> 59918 (1.52%)
A10: /showroom/rumion/ | B10: 14.36% | C10: 36107 | D10: =C10/$I$4 -> 0.0091326684 | E10: =TEXT(C10, "0") & CHAR(10) &"("& TEXT(D10, "0.00%")&")" -> 36107 (0.91%)
A11: /showroom/urbancruiser-hyryder/ | B11: 50.61% | C11: 434357 | D11: =C11/$I$4 -> 0.10986342 | E11: =TEXT(C11, "0") & CHAR(10) &"("& TEXT(D11, "0.00%")&")" -> 434357 (10.99%)
A12: /showroom/urbancruiser-taisor/ | B12: 13.97% | C12: 103956 | D12: =C12/$I$4 -> 0.026293951 | E12: =TEXT(C12, "0") & CHAR(10) &"("& TEXT(D12, "0.00%")&")" -> 103956 (2.63%)
A13: /showroom/vellfire/ | B13: 63.26% | C13: 273093 | D13: =C13/$I$4 -> 0.069074357 | E13: =TEXT(C13, "0") & CHAR(10) &"("& TEXT(D13, "0.00%")&")" -> 273093 (6.91%)

Sheet Site - Month Graph
C1: Page Views
C3: Date(mm/dd/yyyy) | D3: Page Views(Overall) | E3: Page Views(Mobile)
C4: 01-10-2025 | D4: 126565 | E4: 97703
C5: 02-10-2025 | D5: 130057 | E5: 106679
C6: 03-10-2025 | D6: 138605 | E6: 107562
C7: 04-10-2025 | D7: 142086 | E7: 111731
C8: 05-10-2025 | D8: 135770 | E8: 114163
C9: 06-10-2025 | D9: 147871 | E9: 113322
C10: 07-10-2025 | D10: 138958 | E10: 107444
C11: 08-10-2025 | D11: 131119 | E11: 98620
C12: 09-10-2025 | D12: 128450 | E12: 96686
C13: 10-10-2025 | D13: 125979 | E13: 96091
C14: 11-10-2025 | D14: 121732 | E14: 95271
C15: 12-10-2025 | D15: 116690 | E15: 95292
... C33: 30-10-2025 | D33: 117554 | E33: 89681
C34: 31-10-2025 | D34: 113514 | E34: 87906 | H34: =D35 & " pages has been viewed overall, average page view per day is " & D36 & ". Page views - lowest on " & TEXT(D38, "dddd, mmmm dd") & IF(OR(DAY(D38)=1, DAY(D38)=21, DAY(D38)=31), "st", IF(OR(DAY(D38)=2, DAY(D38)=22), "nd", IF(OR(DAY(D38)=3, DAY(D38)=23), "rd", "th"))) & ", " & TEXT(D38, "yyyy") & " (" & D37 & "). " & E35 & " pages has been viewed only on mobile, average page view per day is " & E36 & ". Page views - lowest on " & TEXT(E38, "dddd, mmmm dd") & IF(OR(DAY(E38)=1, DAY(E38)=21, DAY(E38)=31), "st", IF(OR(DAY(E38)=2, DAY(E38)=22), "nd", IF(OR(DAY(E38)=3, DAY(E38)=23), "rd", "th"))) & ", " & TEXT(E38, "yyyy") & " (" & E37 & ")." -> 3953609 pages has been viewed overall, average page view per day is 127536. Page views - lowest on Monday, October 20th, 2025 (103954). 3081214 pages has been viewed only on mobile, average page view per day is 99394. Page views - lowest on Monday, October 20th, 2025 (84104).
C35: Totall | D35: =SUM(D4:D34) -> 3953609 | E35: =SUM(E4:E34) -> 3081214
C36: Average per day | D36: =ROUND(AVERAGE(D4:D34),0) -> 127536 | E36: =ROUND(AVERAGE(E4:E34),0) -> 99394
C37: lowest | D37: =MIN(D4:D34) -> 103954 | E37: =MIN(E4:E34) -> 84104
C38: lowest On | D38: =INDEX(C4:C34,MATCH(MIN(D4:D34),D4:D34,0)) -> 20-10-2025 | E38: =INDEX(C4:C34,MATCH(MIN(E4:E34),E4:E34,0)) -> 20-10-2025
C42: Unique Visit
C44: Date(mm/dd/yyyy) | D44: Unique Visit(Overall) | E44: Unique Visit(Mobile)
C45: 01-10-2025 | D45: 52183 | E45: 45356
C46: 02-10-2025 | D46: 55606 | E46: 49077
C47: 03-10-2025 | D47: 59125 | E47: 51027
C48: 04-10-2025 | D48: 59705 | E48: 52729
C49: 05-10-2025 | D49: 58354 | E49: 52795
C50: 06-10-2025 | D50: 64107 | E50: 55545
C51: 07-10-2025 | D51: 59707 | E51: 52016
C52: 08-10-2025 | D52: 53775 | E52: 45619
C53: 09-10-2025 | D53: 51910 | E53: 44003
C54: 10-10-2025 | D54: 51778 | E54: 44240
C55: 11-10-2025 | D55: 48925 | E55: 42716
C56: 12-10-2025 | D56: 47080 | E56: 41834
... C75: 31-10-2025 | D75: 47933 | E75: 41991
D76: =SUM(D45:D75) -> 1673657 | E76: =SUM(E45:E75) -> 1435799
D77: =ROUND(AVERAGE(D45:D75),0) -> 53989 | E77: =ROUND(AVERAGE(E45:E75),0) -> 46316

Sheet No of Visitors
A1: Date | B1: Visits | C1: Date | D1: Visits
A2: May-2025 | B2: 1386083 | C2: May-2025 | D2: 1127700
A3: Jun-2025 | B3: 3436416 | C3: Jun-2025 | D3: 3122151
A4: Jul-2025 | B4: 4167538 | C4: Jul-2025 | D4: 3844822
A5: Aug-2025 | B5: 1883860 | C5: Aug-2025 | D5: 1585494
A6: Sep-2025 | B6: 2306319 | C6: Sep-2025 | D6: 1941298
A7: Oct-2025 | B7: 2295204 | C7: Oct-2025 | D7: 1903070
K32: OVERALL | W32: MOBILE

Sheet Online Requests Trends
A1: Month_Year | B1: Lead
A2: May-2025 | B2: 100509 | E2: Requests | F2: %
A3: Jun-2025 | B3: 114024 | D3: Brochure | E3: 109 | F3: =(E3/E7)*100 -> 0.060505135
A4: Jul-2025 | B4: 113905 | D4: Buy Now | E4: 161934 | F4: =(E4/E7)*100 -> 89.888426
A5: Aug-2025 | B5: 127069 | D5: Grievance | E5: 98 | F5: =(E5/E7)*100 -> 0.054399112
A6: Sep-2025 | B6: 148616 | D6: Test Drive | E6: 18009 | F6: =(E6/E7)*100 -> 9.9966694
A7: Oct-2025 | B7: 180150 | D7: Total | E7: =SUM(E3:E6) -> 180150 | F7: =SUM(F3:F6) -> 100
B14: ="Total Requests: " & E7 & " NOS." -> Total Requests: 180150 NOS.
B15: Enquiry:-
B16: =D4&" : " & E4 & " (" & TEXT(F4, "0.00") & "%)" -> Buy Now : 161934 (89.89%) | C16: =D3&" " & E3 & " (" & TEXT(F3, "0.00") & "%)" -> Brochure 109 (0.06%)
B18: =D5&" : " & E5 & " (" & TEXT(F5, "0.00") & "%)" -> Grievance : 98 (0.05%) | C18: =D6&": " & E6 & " (" & TEXT(F6, "0.00") & "%)" -> Test Drive: 18009 (10.00%)

Sheet Brochure And FlipBook Counts
A1: Car Chapters | B1: Brochure Downloaded Clicks | C1: Car Chapter View Brochure | D1: Flipbook Clicks | E1: Download Brochure Page Views
A2: Download Brochure - Urban Cruiser Hyryder | B2: 96638 | C2: - | D2: 125152 | E2: 303737
A3: Download Brochure - Innova Hycross | B3: 63879 | C3: 3411
A4: Download Brochure - Glanza | B4: 30100 | C4: -
A5: Download Brochure - Urban Cruiser Taisor | B5: 29280 | C5: 6050
A6: Download Brochure - Vellfire | B6: 20190 | C6: -
A7: Download Brochure - Hilux | B7: 16616 | C7: -
A8: Download Brochure - Land Cruiser 300 | B8: 16315 | C8: -
A9: Download Brochure - Camry | B9: 14444 | C9: 10854
A10: Download Brochure - Rumion | B10: 12249 | C10: 3600
A11: Download Brochure - Fortuner | B11: 4706 | C11: 19291
A12: Download Brochure - Innova Crysta | B12: 4224 | C12: 8590
A13: Download Brochure - Legender | B13: 2809 | C13: 8161
A24: https://analytics.google.com/analytics/web/?authuser=0#/p353077807/reports/explorer?params=_u..nav%3Dmaui%26_u.comparisonOption%3Ddisabled%26_u.date00%3D20250101%26_u.date01%3D20250630%26_r..dataFilters%3D%5B%7B%22type%22:1,%22fieldName%22:%22customDimensionsGroup2Slot06%22,%22evaluationType%22:8,%22expressionList%22:%5B%22Download%20Brochure%20-%20Urban%20Cruiser%20Hyryder%22,%22Download%20Brochure%20-%20Innova%20Hycross%22,%22Download%20Brochure%20-%20Urban%20Cruiser%20Taisor%22,%22Download%20Brochure%20-%20Vellfire%22,%22Download%20Brochure%20-%20Hilux%22,%22Download%20Brochure%20-%20Land%20Cruiser%20300%22,%22Download%20Brochure%20-%20Rumion%22,%22Download%20Brochure%20-%20Camry%22,%22Download%20Brochure%20-%20Fortuner%22,%22Download%20Brochure%20-%20Innova%20Crysta%22,%22Download%20Brochure%20-%20Legender%22%5D,%22complement%22:false,%22isCaseSensitive%22:true,%22expression%22:%22%22%7D%5D%26_r.copa-filter-builder..filter-to-edit%3D%5B%7B%22type%22:1,%22fieldName%22:%22customDimensionsGroup2Slot06%22,%22evaluationType%22:8,%22expressionList%22:%5B%22Download%20Brochure%20-%20Urban%20Cruiser%20Hyryder%22,%22Download%20Brochure%20-%20Innova%20Hycross%22,%22Download%20Brochure%20-%20Urban%20Cruiser%20Taisor%22,%22Download%20Brochure%20-%20Vellfire%22,%22Download%20Brochure%20-%20Hilux%22,%22Download%20Brochure%20-%20Land%20Cruiser%20300%22,%22Download%20Brochure%20-%20Rumion%22,%22Download%20Brochure%20-%20Camry%22,%22Download%20Brochure%20-%20Fortuner%22,%22Download%20Brochure%20-%20Innova%20Crysta%22,%22Download%20Brochure%20-%20Legender%22%5D,%22complement%22:false,%22isCaseSensitive%22:true,%22expression%22:%22%22%7D%5D%26_r.explorerCard..seldim%3D%5B%22eventName%22,%22customDimensionsGroup2Slot06%22%5D%26_r.explorerCard..startRow%3D0%26_r.explorerCard..rowsPerPage%3D25&ruid=top-events,life-cycle,engagement&collectionId=6342606963&r=7537197290
A27: Car Chapters | B27: Brochure Downloaded Clicks label name | C27: Car Chapter View Brochure
A28: Glanza | B28: Download Brochure - Glanza | C28: View B
A29: Urban Cruiser Taisor | B29: Download Brochure - Urban Cruiser Taisor | D29: Urban Cruiser Taisor
A30: Rumion | B30: Download Brochure - Rumion | D30: Rumion Tab
A31: Urban Cruiser Hyryder | B31: Download Brochure - Urban Cruiser Hyryder
A32: Innova Crysta | B32: Download Brochure - Innova Crysta | D32: Innova Crysta
A33: Innova Hycross | B33: Download Brochure - Innova Hycross
A34: Hilux | B34: Download Brochure - Hilux
A35: Fortuner | B35: Download Brochure - Fortuner | D35: New Fortuner Tab
A36: Legender | B36: Download Brochure - Legender | D36: Legender Tab
A37: Camry | B37: Download Brochure - Camry | D37: Camry
A38: Vellfire | B38: Download Brochure - Vellfire
A39: Land Cruiser 300 | B39: Download Brochure - Land Cruiser 300

Sheet virtualshowroom
A1: Virtual Showroom Car Chapters | B1: Sessions | C1: Page Views | D1: Avg Time Spent
A2: /virtual-showroom/ | B2: 58917 | C2: 73288 | D2: 2m 53s
A3: /virtual-showroom/urbancruisertaisor.html | B3: 31775 | C3: 39551 | D3: 4m 12s
A4: /virtual-showroom/urbancruiserhyryder.html | B4: 30717 | C4: 36767 | D4: 4m 56s
A5: /virtual-showroom/fortuner.html | B5: 23617 | C5: 30232 | D5: 3m 39s
A6: /virtual-showroom/innova.html | B6: 23580 | C6: 28634 | D6: 5m 02s
A7: /virtual-showroom/lc300.html | B7: 15194 | C7: 19003 | D7: 2m 27s
A8: /virtual-showroom/camry.html | B8: 13866 | C8: 16330 | D8: 2m 57s
A9: /virtual-showroom/legender.html | B9: 10767 | C9: 13970 | D9: 3m 07s
A10: /virtual-showroom/glanza.html | B10: 10226 | C10: 12359 | D10: 5m 05s
A11: /virtual-showroom/innovacrysta.html | B11: 8956 | C11: 10679 | D11: 4m 52s
A12: /virtual-showroom/vellfire.html | B12: 7735 | C12: 9178 | D12: 2m 47s
A13: /virtual-showroom/hilux.html | B13: 4295 | C13: 5328 | D13: 3m 24s
... A16: /virtual-showroom/Innova.html | B16: 62 | C16: 77 | D16: 4m 16s
A20: Virtual Showroom Car Chapters | B20: Sessions | C20: Page Views | D20: Avg Time Spent
A21: /virtual-showroom/ | B21: 565994 | C21: 704924 | D21: 2m 39s
A22: /virtual-showroom/urbancruisertaisor.html | B22: 267831 | C22: 331646 | D22: 3m 58s
A23: /virtual-showroom/camry.html | B23: 235540 | C23: 284537 | D23: 2m 41s
A24: /virtual-showroom/urbancruiserhyryder.html | B24: 233164 | C24: 282992 | D24: 5m 07s
A25: /virtual-showroom/innova.html | B25: 210130 | C25: 259298 | D25: 5m 15s
A26: /virtual-showroom/glanza.html | B26: 197132 | C26: 229404 | D26: 3m 00s
A27: /virtual-showroom/lc300.html | B27: 164836 | C27: 198257 | D27: 2m 15s
A28: /virtual-showroom/fortuner.html | B28: 154360 | C28: 206728 | D28: 4m 04s
A29: /virtual-showroom/legender.html | B29: 115576 | C29: 147610 | D29: 3m 05s
A30: /virtual-showroom/vellfire.html | B30: 114990 | C30: 139422 | D30: 2m 28s
A31: /virtual-showroom/hilux.html | B31: 89012 | C31: 103091 | D31: 2m 27s
A32: /virtual-showroom/innovacrysta.html | B32: 74093 | C32: 93776 | D32: 5m 02s
... A35: /virtual-showroom/Innova.html | B35: 188 | C35: 236 | D35: 3m 46s

Sheet Section Performance
B1: Mothly
A3: S.No | B3: Page path | C3: Pageviews | D3: Percentage | E3: Unique Pageviews | F3: Percentage
A4: 1 | B4: /showroom/camry/ | C4: 435656 | D4: =C4 / $C$14 -> 0.11019198 | E4: 302774 | F4: =E4 / $E$14 -> 0.18090565
A5: 2 | B5: /showroom/urbancruiser-hyryder/ | C5: 434357 | D5: =C5 / $C$14 -> 0.10986342 | E5: 242167 | F5: =E5 / $E$14 -> 0.14469333
A6: 3 | B6: / | C6: 431338 | D6: =C6 / $C$14 -> 0.10909981 | E6: 199590 | F6: =E6 / $E$14 -> 0.11925383
A7: 4 | B7: /showroom/vellfire/ | C7: 273093 | D7: =C7 / $C$14 -> 0.069074357 | E7: 152929 | F7: =E7 / $E$14 -> 0.091374159
A8: 5 | B8: /campaign/urbancruiser-hyryder/ | C8: 220319 | D8: =C8 / $C$14 -> 0.055726047 | E8: 148703 | F8: =E8 / $E$14 -> 0.088849149
A9: 6 | B9: /pricelist/ | C9: 198608 | D9: =C9 / $C$14 -> 0.050234608 | E9: 16518 | F9: =E9 / $E$14 -> 0.0098694057 | U9: / | V9: 3641104 | W9: 2065856
A10: 7 | B10: /showroom/fortuner/index-fortuner.html | C10: 169366 | D10: =C10 / $C$14 -> 0.042838328 | E10: 76013 | F10: =E10 / $E$14 -> 0.045417311 | U10: /showroom/glanza/ | V10: 3627783 | W10: 2578524
A11: 8 | B11: /showroom/innova/ | C11: 135563 | D11: =C11 / $C$14 -> 0.034288419 | E11: 42030 | F11: =E11 / $E$14 -> 0.025112672 | U11: /showroom/urbancruiser-taisor/ | V11: 3046568 | W11: 2061639
A12: 9 | B12: /showroom/glanza/ | C12: 116117 | D12: =C12 / $C$14 -> 0.029369874 | E12: 54567 | F12: =E12 / $E$14 -> 0.032603455 | U12: /showroom/camry/ | V12: 2590701 | W12: 1196886
A13: 10 | B13: /showroom/innova-crysta/ | C13: 104335 | D13: =C13 / $C$14 -> 0.026389812 | E13: 35774 | F13: =E13 / $E$14 -> 0.02137475 | U13: /showroom/urbancruiser-hyryder/ | V13: 1893051 | W13: 1142366
C14: 3953609 | D14: =SUM(D4:D13) -> 0.63707666 | E14: 1673657 | F14: =SUM(F4:F13) -> 0.7594537 | U14: /showroom/innova/ | V14: 1560879 | W14: 981618
U15: /campaign/glanza/index.html | V15: 1258673 | W15: 803479
U16: /showroom/fortuner/index-fortuner.html | V16: 976564 | W16: 668485
A17: =" - Top 10 sections constitute " & TEXT(D14, "0.00%") & " of Page views. (Total Page views – " & TEXT(C14, "#,##0") & ")" & CHAR(10) & " - " & TEXT(F14, "0.00%") & " of page views are unique Page views for top 10 sections." -> - Top 10 sections constitute 63.71% of Page views. (Total Page views – 39,53,609) - 75.95% of page views are unique Page views for top 10 sections. | B17: /showroom/urbancruiser-taisor/ | C17: 92195 | E17: 16446 | U17: /pricelist/ | V17: 859398 | W17: 517912
B18: /campaign/glanza/index.html | C18: 84553 | E18: 72113 | U18: /showroom/innova-crysta/ | V18: 822530 | W18: 564497
B25: YEAR TO TILL
A27: S.No | B27: Page path | C27: Pageviews | D27: Percentage | E27: Unique Pageviews | F27: Percentage | T27: Toyota Camry | U27: 2542304 | V27: 48384 | W27: =SUM(U27:V27) -> 2590688
A28: 1 | B28: / | C28: 4354608 | D28: =C28/ $C$38 -> 0.11806631 | E28: 2059610 | F28: =E28 / $E$38 -> 0.13656415 | T28: Toyota Fortuner | U28: 896824 | V28: 111688 | W28: =SUM(U28:V28) -> 1008512
A29: 2 | B29: /showroom/vellfire/ | C29: 3515747 | D29: =C29/ $C$38 -> 0.095322307 | E29: 2212061 | F29: =E29 / $E$38 -> 0.14667254 | T29: Toyota Legender | U29: 264833 | V29: 44444 | W29: =SUM(U29:V29) -> 309277
A30: 3 | B30: /showroom/glanza/ | C30: 3180166 | D30: =C30/ $C$38 -> 0.086223713 | E30: 1926637 | F30: =E30 / $E$38 -> 0.12774727 | T30: Toyota Glanza | U30: 3566533 | V30: 61226 | W30: =SUM(U30:V30) -> 3627759
A31: 4 | B31: /showroom/camry/ | C31: 2614892 | D31: =C31/ $C$38 -> 0.070897461 | E31: 1319060 | F31: =E31 / $E$38 -> 0.087461369 | T31: Toyota Hilux | U31: 541489 | V31: 43347 | W31: =SUM(U31:V31) -> 584836
A32: 5 | B32: /showroom/urbancruiser-hyryder/ | C32: 2381580 | D32: =C32/ $C$38 -> 0.064571683 | E32: 1116361 | F32: =E32 / $E$38 -> 0.074021243 | T32: Toyota Innova Crysta | U32: 934355 | V32: 84613 | W32: =SUM(U32:V32) -> 1018968
A33: 6 | B33: /pricelist/ | C33: 1912540 | D33: =C33/ $C$38 -> 0.05185462 | E33: 148244 | F33: =E33 / $E$38 -> 0.0098294415 | T33: Toyota Innova Hycross | U33: 1173201 | V33: 191154 | W33: =SUM(U33:V33) -> 1364355
A34: 7 | B34: /showroom/innova/ | C34: 1750094 | D34: =C34/ $C$38 -> 0.047450228 | E34: 760295 | F34: =E34 / $E$38 -> 0.050411991 | T34: Toyota Lc300 | U34: 284393 | V34: 33640 | W34: =SUM(U34:V34) -> 318033
A35: 8 | B35: /showroom/urbancruiser-taisor/ | C35: 1193473 | D35: =C35/ $C$38 -> 0.032358585 | E35: 390008 | F35: =E35 / $E$38 -> 0.025859804 | T35: Toyota Rumion | U35: 466357 | V35: 42511 | W35: =SUM(U35:V35) -> 508868
A36: 9 | B36: /showroom/fortuner/index-fortuner.html | C36: 1179052 | D36: =C36/ $C$38 -> 0.031967589 | E36: 488040 | F36: =E36 / $E$38 -> 0.032359897 | T36: Toyota Urbancruiser Hyryder | U36: 1752895 | V36: 140112 | W36: =SUM(U36:V36) -> 1893007
A37: 10 | B37: /showroom/innova-crysta/ | C37: 1139472 | D37: =C37/ $C$38 -> 0.030894458 | E37: 521109 | F37: =E37 / $E$38 -> 0.034552565 | T37: Toyota Urbancruiser Taisor | U37: 2468266 | V37: 578266 | W37: =SUM(U37:V37) -> 3046532
B38: Tottal | C38: 36882731 | D38: =SUM(D28:D37) -> 0.62960696 | E38: 15081630 | F38: =SUM(F28:F37) -> 0.72548027 | T38: Toyota Vellfire | U38: 282210 | V38: 37096 | W38: =SUM(U38:V38) -> 319306
W39: =SUM(W27:W38) -> 16590141
A40: =" - Top 10 sections constitute " & TEXT(D38, "0.00%") & " of Page views. (Total Page views – " & TEXT(C38, "#,##0") & ")" & CHAR(10) & " - " & TEXT(F38, "0.00%") & " of page views are unique Page views for top 10 sections." -> - Top 10 sections constitute 62.96% of Page views. (Total Page views – 3,68,82,731) - 72.55% of page views are unique Page views for top 10 sections.

Sheet Traffic source
A1: Default Channel Grouping | B1: Sessions | C1: %
A2: Organic Search | B2: 826161 | C2: =B2/$B$19*100 -> 35.995101
A3: Display | B3: 525246 | C3: =B3/$B$19*100 -> 22.884502
A4: Paid Search | B4: 354451 | C4: =B4/$B$19*100 -> 15.443115
A5: Unassigned | B5: 228757 | C5: =B5/$B$19*100 -> 9.9667393
A6: Paid Social | B6: 133993 | C6: =B6/$B$19*100 -> 5.837956
A7: Direct | B7: 106292 | C7: =B7/$B$19*100 -> 4.631048
A8: Organic Social | B8: 92719 | C8: =B8/$B$19*100 -> 4.0396845
A9: Referral | B9: 16835 | C9: =B9/$B$19*100 -> 0.733486
A10: Cross-network | B10: 10744 | C10: =B10/$B$19*100 -> 0.46810654
A11: Organic Shopping | B11: 4516 | C11: =B11/$B$19*100 -> 0.19675811
A12: Paid Other | B12: 2859 | C12: =B12/$B$19*100 -> 0.12456409
A13: Mobile Push Notifications | B13: 745 | C13: =B13/$B$19*100 -> 0.032458988
... A17: Email | B17: 1 | C17: =B17/$B$19*100 -> 4.3569112e-05
B19: 2295204
A23: Organic Search | B23: 589980 | C23: =B23/$B$19*100 -> 25.704905
A24: Display | B24: 498702 | C24: =B24/$B$19*100 -> 21.728003
A25: Paid Search | B25: 341586 | C25: =B25/$B$19*100 -> 14.882599
A26: Unassigned | B26: 171047 | C26: =B26/$B$19*100 -> 7.4523659
A27: Paid Social | B27: 132388 | C27: =B27/$B$19*100 -> 5.7680276
A28: Organic Social | B28: 90331 | C28: =B28/$B$19*100 -> 3.9356415
A29: Direct | B29: 83636 | C29: =B29/$B$19*100 -> 3.6439462
A30: Referral | B30: 10670 | C30: =B30/$B$19*100 -> 0.46488242
A31: Cross-network | B31: 10405 | C31: =B31/$B$19*100 -> 0.45333661
A32: Organic Shopping | B32: 4390 | C32: =B32/$B$19*100 -> 0.1912684
A33: Paid Other | B33: 2465 | C33: =B33/$B$19*100 -> 0.10739786
A34: Mobile Push Notifications | B34: 431 | C34: =B34/$B$19*100 -> 0.018778287
... A38: Email | B38: 2 | C38: =B38/$B$19*100 -> 8.7138224e-05
B39: 1903070
A44: overall | G44: mobile
A46: SOURCES | B46: VISITS | C46: % VISITS | G46: SOURCES | H46: VISITS | I46: % VISITS
A47: google / organic | B47: 799254 | C47: =B47/$B$19 -> 0.34822787 | G47: google / organic | H47: 586468 | I47: =H47/$B$39 -> 0.30816943
A48: google / cpc | B48: 405333 | C48: =B48/$B$19 -> 0.17659999 | G48: google / cpc | H48: 393102 | I48: =H48/$B$39 -> 0.20656203
A49: nobroker / cpm | B49: 158245 | C49: =B49/$B$19 -> 0.068945941 | G49: nobroker / cpm | H49: 157405 | I49: =H49/$B$39 -> 0.082711093
A50: (direct) / (none) | B50: 106292 | C50: =B50/$B$19 -> 0.04631048 | G50: facebook / cpl | H50: 86844 | I50: =H50/$B$39 -> 0.045633634
A51: facebook / cpl | B51: 88034 | C51: =B51/$B$19 -> 0.038355632 | G51: (direct) / (none) | H51: 83636 | I51: =H51/$B$39 -> 0.043947937
A52: twitter / form | B52: 70745 | C52: =B52/$B$19 -> 0.030822968 | G52: twitter / form | H52: 68540 | I52: =H52/$B$39 -> 0.036015491
A53: dailyhunt / cpm | B53: 56365 | C53: =B53/$B$19 -> 0.02455773 | G53: dailyhunt / cpm | H53: 55711 | I53: =H53/$B$39 -> 0.029274278
A54: dv360 / form | B54: 55443 | C54: =B54/$B$19 -> 0.024156023 | G54: dv360 / form | H54: 50515 | I54: =H54/$B$39 -> 0.026543953
A55: mediakart / form | B55: 55005 | C55: =B55/$B$19 -> 0.02396519 | G55: facebook / cpc | H55: 46469 | I55: =H55/$B$39 -> 0.024417914
...

Sheet age&gender
A1: userAgeBracket | B1: sessions | C1: %
A2: unknown | B2: 1709228 | C2: =SUM(B2/D2) -> 0.74469546 | D2: ='Traffic source'!$B$19 -> 2295204
A3: 25-34 | B3: 196054 | C3: =SUM(B3/D3) -> 0.085418987 | D3: ='Traffic source'!$B$19 -> 2295204
A4: 35-44 | B4: 141059 | C4: =SUM(B4/D4) -> 0.061458154 | D4: ='Traffic source'!$B$19 -> 2295204
A5: 18-24 | B5: 137720 | C5: =SUM(B5/D5) -> 0.060003381 | D5: ='Traffic source'!$B$19 -> 2295204
A6: 45-54 | B6: 68068 | C6: =SUM(B6/D6) -> 0.029656623 | D6: ='Traffic source'!$B$19 -> 2295204
A7: 55-64 | B7: 34165 | C7: =SUM(B7/D7) -> 0.014885387 | D7: ='Traffic source'!$B$19 -> 2295204
A8: 65+ | B8: 17110 | C8: =SUM(B8/D8) -> 0.0074546751 | D8: ='Traffic source'!$B$19 -> 2295204
A9: (other) | B9: 58
A30: userGender | B30: sessions | C30: %
A31: unknown | B31: 1640292 | C31: =SUM(B31/D6) -> 0.71466066
A32: male | B32: 552487 | C32: =SUM(B32/D7) -> 0.24071368
A33: female | B33: 104914 | C33: =B33/D3 -> 0.045710098
A34: (other) | B34: 58

Sheet browser
B1: Sessions | C1: % | D1: Users | G1: totalvisits
A2: Chrome | B2: 1426397 | C2: =B2/$G$2 -> 0.62146851 | D2: 970457 | G2: ='No of Visitors'!B7 -> 2295204
A3: Safari | B3: 481609 | C3: =B3/$G$2 -> 0.20983276 | D3: 372690
A4: Android Webview | B4: 164339 | C4: =B4/$G$2 -> 0.071601043 | D4: 156300
A5: Safari (in-app) | B5: 95702 | C5: =B5/$G$2 -> 0.041696512 | D5: 89409
A6: Samsung Internet | B6: 58191 | C6: =B6/$G$2 -> 0.025353302 | D6: 35237
A7: Edge | B7: 42195 | C7: =B7/$G$2 -> 0.018383987 | D7: 25459
A8: Firefox | B8: 18344 | C8: =B8/$G$2 -> 0.0079923179 | D8: 14006
A9: Opera | B9: 9124 | C9: =B9/$G$2 -> 0.0039752458 | D9: 6176
A10: Internet Explorer | B10: 1705 | C10: =B10/$G$2 -> 0.00074285336 | D10: 1707
A11: UC Browser | B11: 502 | C11: =B11/$G$2 -> 0.00021871694 | D11: 438
A12: Mozilla Compatible Agent | B12: 466 | C12: =B12/$G$2 -> 0.00020303206 | D12: 460
A13: Android Browser | B13: 446 | D13: 441
A14: Puffin | B14: 296 | D14: 296
A15: (not set) | B15: 230 | D15: 228
A16: YaBrowser | B16: 219 | D16: 218

Sheet operatingSystem
B1: Sessions | C1: % | D1: Users | F1: totalvisits
A2: Android | B2: 1301007 | C2: =B2/$F$2 -> 0.5668372 | D2: 929620 | F2: ='Traffic source'!B19 -> 2295204
A3: iOS | B3: 632070 | C3: =B3/$F$2 -> 0.27538729 | D3: 516434
A4: Windows | B4: 249111 | C4: =B4/$F$2 -> 0.10853545 | D4: 159603
A5: Macintosh | B5: 81448 | C5: =B5/$F$2 -> 0.03548617 | D5: 46980
A6: Linux | B6: 29927 | C6: =B6/$F$2 -> 0.013038928 | D6: 19410
A7: Chrome OS | B7: 1566 | C7: =B7/$F$2 -> 0.00068229229 | D7: 1239
A8: (not set) | B8: 171 | C8: =B8/$F$2 -> 7.4503181e-05 | D8: 169
A9: Windows Phone | B9: 150 | C9: =B9/$F$2 -> 6.5353668e-05 | D9: 150
A10: Tizen | B10: 67 | C10: =B10/$F$2 -> 2.9191305e-05 | D10: 44
A11: Fuchsia | B11: 2 | C11: =B11/$F$2 -> 8.7138224e-07 | D11: 2
A12: OS/2 | B12: 2 | C12: =B12/$F$2 -> 8.7138224e-07 | D12: 2
A13: Xbox | B13: 2 | D13: 2
A14: FreeBSD | B14: 1 | D14: 1
A15: Playstation 4 | B15: 1 | D15: 1

Sheet Landing&Exits
A1: PAGE | B1: VISITS | C1: PAGES / VISITS | D1: Views
A2: /showroom/camry | B2: 339804 | C2: 1.3051524 | D2: 443496
A3: /showroom/urbancruiser-hyryder | B3: 315407 | C3: 1.4191505 | D3: 447610
A4: / | B4: 304923 | C4: 3.3800107 | D4: 1030643
A5: /showroom/vellfire | B5: 219055 | C5: 1.2568533 | D5: 275320
A6: /campaign/urbancruiser-hyryder | B6: 193863 | C6: 1.226624 | D6: 237797
A7: /showroom/fortuner/index-fortuner.html | B7: 98202 | C7: 1.7906865 | D7: 175849 | E7: <=== OverAll
A8: /showroom/glanza | B8: 67267 | C8: 1.4307759 | D8: 96244
A9: /campaign/glanza/index.html | B9: 65507 | C9: 1.2797258 | D9: 83831
A10: /campaign/vellfire/index.html | B10: 64809 | C10: 1.1509204 | D10: 74590
A11: /campaign/lc300/index.html | B11: 64051 | C11: 1.0940344 | D11: 70074
A12: /showroom/innova | B12: 63762 | C12: 2.3007748 | D12: 146702
A13: (not set) | B13: 53505 | C13: 7.4759368e-05 | D13: 4
A14: /showroom/innova-crysta | B14: 50049 | C14: 1.8337429 | D14: 91777
A15: /pricelist | B15: 39414 | C15: 1.8800934 | D15: 74102
A16: /showroom/urbancruiser-taisor | B16: 30203 | C16: 2.2521935 | D16: 68023
A20: /showroom/vellfire | B20: 393139 | C20: 1.2029918 | D20: 472943
A21: /showroom/urbancruiser-hyryder | B21: 279009 | C21: 1.3783247 | D21: 384565
A22: /showroom/camry | B22: 275241 | C22: 1.2569821 | D22: 345973
A23: / | B23: 218232 | C23: 3.0941521 | D23: 675243 | E23: <=== mobile
A24: /showroom/vellfire | B24: 205935 | C24: 1.2573191 | D24: 258926
A25: /campaign/urbancruiser-hyryder | B25: 189121 | C25: 1.2160469 | D25: 229980
A26: /showroom/fortuner/index-fortuner.html | B26: 87553 | C26: 1.6849223 | D26: 147520
A27: /campaign/glanza/index.html | B27: 64747 | C27: 1.2722752 | D27: 82376
A28: /campaign/lc300/index.html | B28: 63800 | C28: 1.0896395 | D28: 69519
A29: /campaign/vellfire/index.html | B29: 63349 | C29: 1.1386447 | D29: 72132
A30: /showroom/glanza | B30: 58060 | C30: 1.3537031 | D30: 78596
A31: /showroom/innova | B31: 46107 | C31: 2.0041425 | D31: 92405
A32: /showroom/innova-crysta | B32: 39789 | C32: 1.7398025 | D32: 69225
A33: /pricelist | B33: 33862 | C33: 1.7981218 | D33: 60888
A34: (not set) | B34: 22950 | C34: 8.7145969e-05 | D34: 2
A35: /campaign/hilux | B35: 22528 | C35: 1.5021751 | D35: 33841

Sheet kpimonthly
A1: Sl. No. | B1: Pages | C1: Avg. Load Time | D1: Bounce Rate | E1: Time Spent | F1: Total Pageviews | G1: Per day Avg | H1: Total Unique Pageviews | I1: Per day Avg.
A2: 1 | B2: Overall Website (Avg) | C2: 6.15 | D2: 0.5507 | E2: 0.0016319444 | F2: ='Site - Month Graph'!D35 -> 3953609 | G2: =F2/330 -> 11980.633 | H2: 1772011 | I2: =H2/31 -> 57161.645
A3: 2 | B3: Home Page | C3: 6.2 | D3: 0.15939009 | E3: 00:01:15 | F3: 431338 | G3: 13914.129 | H3: 264713 | I3: 8539.129 | J3: /
A4: 3 | B4: Product Pages (Avg) | C4: 6.45 | D4: 0.5 | E4: 00:00:29 | F4: 12 | G4: 0.38709677 | H4: 8 | I4: 0.25806452 | J4: /Showroom/fortuner/index-legender.html
A5: 3.1 | B5: Camry | C5: 5.4 | D5: 0.70074484 | E5: 0.00069444444 | F5: 374831 | G5: 12494.367 | H5: 235224 | I5: 7840.8
A6: 3.2 | B6: Fortuner | C6: 5.9 | D6: 0 | E6: 00:00:18 | F6: 2 | G6: 0.064516129 | H6: 1 | I6: 0.032258065 | J6: /showroom/Innova/
A7: 3.3 | B7: Legender | C7: 5.3 | D7: 0.7 | E7: 00:00:57 | F7: 12 | G7: 0.38709677 | H7: 2 | I7: 0.064516129 | J7: /showroom/Rumion/
A8: 3.4 | B8: Glanza | C8: 4.5 | D8: 0 | E8: 00:00:07 | F8: 2 | G8: 0.064516129 | H8: 1 | I8: 0.032258065 | J8: /showroom/UrbanCruiser-hyryder/
A9: 3.5 | B9: Hilux | C9: 8.6 | D9: 0.68595902 | E9: 00:00:52 | F9: 435656 | G9: 14053.419 | H9: 335662 | I9: 10827.806 | J9: /showroom/camry/
A10: 3.6 | B10: Innova Crysta | C10: 7 | D10: 0.36042436 | E10: 00:01:37 | F10: 169366 | G10: 5463.4194 | H10: 116190 | I10: 3748.0645 | J10: /showroom/fortuner/index-fortuner.html
A11: 3.7 | B11: Innova Hycross | C11: 7.7 | D11: 0.14707775 | E11: 00:01:28 | F11: 42240 | G11: 1362.5806 | H11: 31607 | I11: 1019.5806 | J11: /showroom/fortuner/index-legender.html
A12: 3.8 | B12: LC300 | C12: 5 | D12: 0.41689144 | E12: 00:01:30 | F12: 116117 | G12: 3745.7097 | H12: 86933 | I12: 2804.2903 | J12: /showroom/glanza/
A13: 3.9 | B13: Rumion | C13: 7.3 | D13: 0.18301542 | E13: 00:02:01 | F13: 43786 | G13: 1412.4516 | H13: 31330 | I13: 1010.6452 | J13: /showroom/hilux/
A14: 3.1 | B14: UC Hyryder | C14: 5.7 | D14: 0.21859956 | E14: 00:01:56 | F14: 104335 | G14: 3365.6452 | H14: 74414 | I14: 2400.4516 | J14: /showroom/innova-crysta/
A15: 3.11 | B15: UC Taisor | C15: 8.6 | D15: 0.1568481 | E15: 00:02:46 | F15: 135563 | G15: 4373 | H15: 90409 | I15: 2916.4194 | J15: /showroom/innova/
A16: 3.12 | B16: Vellfire | C16: 6.5 | D16: 0.21618948 | E16: 00:01:41 | F16: 59918 | G16: 1932.8387 | H16: 44686 | I16: 1441.4839 | J16: /showroom/lc300/
A17: 4 | B17: Mobility Solution | C17: 2.4 | D17: 0.14364782 | E17: 00:02:13 | F17: 36107 | G17: 1164.7419 | H17: 26228 | I17: 846.06452 | J17: /showroom/rumion/
D18: 0.50614978 | E18: 00:01:23 | F18: 434357 | G18: 14011.516 | H18: 300380 | I18: 9689.6774 | J18: /showroom/urbancruiser-hyryder/
D19: 0.13969974 | E19: 00:02:18 | F19: 103956 | G19: 3353.4194 | H19: 63591 | I19: 2051.3226 | J19: /showroom/urbancruiser-taisor/
D20: 0.63256382 | E20: 00:01:10 | F20: 273093 | G20: 8809.4516 | H20: 187170 | I20: 6037.7419 | J20: /showroom/vellfire/
A30: Sl. No. | B30: Pages | C30: Bounce Rate | D30: Time Spent | E30: Total Pageviews | F30: Per day Avg | G30: Total Unique Pageviews | H30: Per day Avg.
A31: 1 | B31: Overall Website (Avg) | C31: 0.5276 | D31: 0.0016666667 | E31: 32929122 | F31: =E31/244 -> 134955.42 | G31: 13785194 | H31: =G31/244 -> 56496.697
A32: 2 | B32: Home Page | C32: 0.21594116 | D32: 00:01:12 | E32: 4354608 | F32: 14324.368 | G32: 2440601 | H32: 8028.2928 | I32: /
A33: 3 | B33: Product Pages (Avg) | C33: =AVERAGE(C34:C45) -> 0.40174291 | D33: =AVERAGE(D34:D45) -> #DIV/0! | E33: =AVERAGE(E34:E45) -> 1631680.1 | F33: =AVERAGE(F34:F45) -> 5367.3687 | G33: =AVERAGE(G34:G45) -> 1086432 | H33: =AVERAGE(H34:H45) -> 3573.7895
A34: 3.1 | B34: Camry | C34: 0.6133776 | D34: 00:01:04 | E34: 2614892 | F34: 8601.6184 | G34: 1569925 | H34: 5164.227 | I34: /showroom/camry/
A35: 3.2 | B35: Fortuner | C35: 0.34055247 | D35: 00:01:34 | E35: 1179052 | F35: 3878.4605 | G35: 788565 | H35: 2593.9638 | I35: /showroom/fortuner/index-fortuner.html
A36: 3.3 | B36: Legender | C36: 0.51146908 | D36: 00:01:01 | E36: 825660 | F36: 2715.9868 | G36: 559073 | H36: 1839.0559 | I36: /showroom/fortuner/index-legender.html
A37: 3.4 | B37: Glanza | C37: 0.60233493 | D37: 00:01:26 | E37: 3180166 | F37: 10461.072 | G37: 2155076 | H37: 7089.0658 | I37: /showroom/glanza/
A38: 3.5 | B38: Hilux | C38: 0.43242619 | D38: 00:01:22 | E38: 985046 | F38: 3240.2829 | G38: 742023 | H38: 2440.8651 | I38: /showroom/hilux/
A39: 3.6 | B39: Innova Crysta | C39: 0.3632242 | D39: 00:01:36 | E39: 1139472 | F39: 3748.2632 | G39: 820853 | H39: 2700.1743 | I39: /showroom/innova-crysta/
A40: 3.7 | B40: Innova Hycross | C40: 0.26271329 | D40: 00:02:53 | E40: 1750094 | F40: 5756.8882 | G40: 1151888 | H40: 3789.1053 | I40: /showroom/innova/
A41: 3.8 | B41: LC300 | C41: 0.20477768 | D41: 00:01:44 | E41: 460512 | F41: 1514.8421 | G41: 334177 | H41: 1099.2664 | I41: /showroom/lc300/
A42: 3.9 | B42: Rumion | C42: 0.12165732 | D42: 00:02:56 | E42: 354467 | F42: 1166.0099 | G42: 241898 | H42: 795.71711 | I42: /showroom/rumion/
A43: 3.1 | B43: UC Hyryder | C43: 0.38063206 | D43: 00:01:54 | E43: 2381580 | F43: 7834.1447 | G43: 1515200 | H43: 4984.2105 | I43: /showroom/urbancruiser-hyryder/
A44: 3.11 | B44: UC Taisor | C44: 0.33892426 | D44: 00:01:46 | E44: 1193473 | F44: 3925.898 | G44: 755785 | H44: 2486.1349 | I44: /showroom/urbancruiser-taisor/
A45: 3.12 | B45: Vellfire | C45: 0.64882579 | D45: 00:01:12 | E45: 3515747 | F45: 11564.957 | G45: 2402721 | H45: 7903.6875 | I45: /showroom/vellfire/
A46: 4 | B46: Mobility Solution | C46: 0.061861834 | D46: 00:01:02 | E46: 76643 | F46: 252.11513 | G46: 56681 | H46: 186.45066 | I46: /mobility-solutions/

Sheet tfsinKpi
A1: No. of Monthly Visitors (Toyotabharat website) | B1: ='No of Visitors'!B7 -> 2295204
A2: Online Enquiries/Leads(organic leads) | B2: ='tbltransaction-organic'!N8 -> 6180
A3: No. of Visitors for TFS Landing Page | B3: 2022
A4: No. of Visitors for EMI Calculator | B4: 5813
A5: No. of Apply for Loan Clicks | B5: 1804
A6: No. of Clicks on TFS Logo placed on Page Footer | B6: 560

Sheet referringSites
A1: SOURCE | B1: VISITS | C1: PAGES/VISIT | D1: Views
A2: toyotapartsconnect.in / referral | B2: 1290 | C2: =D2/B2 -> 2.2744186 | D2: 2934
A3: toyotafinance.co.in / referral | B3: 1167 | C3: =D3/B3 -> 2.3521851 | D3: 2745
A4: surveys.numr.app / referral | B4: 857 | C4: =D4/B4 -> 1.3138856 | D4: 1126
A5: chatgpt.com / referral | B5: 761 | C5: =D5/B5 -> 2.1590013 | D5: 1643
A6: bharattoyota.com / referral | B6: 582 | C6: =D6/B6 -> 5.1237113 | D6: 2982
A7: nippon-toyota.com / referral | B7: 568 | C7: =D7/B7 -> 2.2024648 | D7: 1251
A8: jobsaddafreshers.com / referral | B8: 506 | C8: =D8/B8 -> 1.5434783 | D8: 781
A9: drum-tao.com / referral | B9: 489 | C9: =D9/B9 -> 1.5051125 | D9: 736
A10: l.wl.co / referral | B10: 431 | C10: =D10/B10 -> 2.1786543 | D10: 939
A11: millennium-toyota.com / referral | B11: 331 | C11: =D11/B11 -> 2.652568 | D11: 878
A12: harshatoyota.com / referral | B12: 315 | C12: =D12/B12 -> 2.5079365 | D12: 790
A13: nanditoyota.com / referral | B13: 306 | C13: =D13/B13 -> 2.2385621 | D13: 685
... A16: anaamalaistoyota.com / referral | B16: 258 | C16: =D16/B16 -> 1.9844961 | D16: 512
B4387: =SUM(B2:B4386) -> 8462 | D4387: =SUM(D2:D4386) -> 19290 | E4387: =D4387/B4387 -> 2.2796029

Sheet daywiseOneMonthVisits
D1: 01 | F1: 02 | H1: 03 | J1: 04 | L1: 05 | N1: 06 | P1: 07 | R1: 08
C2: Users | D2: 1282252 | F2: 907472 | H2: 1023639 | J2: 838837 | L2: 1111927 | N2: 2761059 | P2: 3349424 | R2: 796861
C3: Visits (Sessions) | D3: 1750181 | F3: 1300740 | H3: 1298056 | J3: 1123222 | L3: 1386083 | N3: 3436416 | P3: 4167538 | R3: 1013091
C4: Average Time on Site | D4: 141.91061 | F4: 160.32509968953289 | H4: 167.84903 | J4: 194.26855 | L4: 192.99797452930019 | N4: 123.9368 | P4: 117.77713 | R4: 173.41305
C5: Unique Users | D5: 1190484 | F5: 786757 | H5: 942198 | J5: 763581 | L5: 1033522 | N5: 2627860 | P5: 3131840 | R5: 675742
C6: Page Views | D6: 3144863 | F6: 2467315 | H6: 2458860 | J6: 2268137 | L6: 2863687 | N6: 5582723 | P6: 6812079 | R6: 1857074
D8: 01 | F8: 02 | H8: 03 | J8: 04 | L8: 05 | N8: 06 | P8: 07 | R8: 08
C9: Users | D9: 752812 | F9: 1952754 | H9: 1088842 | J9: 1822296 | L9: 1853288 | N9: 1647389 | P9: 1931770 | R9: 1196522
C10: Visits (Sessions) | D10: 975150 | F10: 2626352 | H10: 1505441 | J10: 2274026 | L10: 2295053 | N10: 2072987 | P10: 2318344 | R10: 1685981
C11: Average Time on Site | D11: 203.00204 | F11: 144.00022 | H11: 146.44372248043729 | J11: 138.74365894955909 | L11: 131.81292 | N11: 127.72968 | P11: 122.84738 | R11: 150.96375
C12: Unique Users | D12: 686734 | F12: 1860236 | H12: 1019478 | J12: 1696705 | L12: 1743838 | N12: 1538599 | P12: 1786408 | R12: 1131167
C13: Page Views | D13: 1954636 | F13: 4344916 | H13: 2538338 | J13: 3850224 | L13: 3699781 | N13: 3314614 | P13: 3748100 | R13: 2932771
C14: page/visti | D14: =D13/D10 -> 2.0044465 | F14: =F13/F10 -> 1.654354 | H14: =H13/H10 -> 1.6861093 | J14: =J13/J10 -> 1.693131 | L14: =L13/L10 -> 1.6120678 | N14: =N13/N10 -> 1.5989555 | P14: =P13/P10 -> 1.6167143 | R14: =R13/R10 -> 1.7395042
D15: 2.0044465 | F15: 1.654354 | H15: 1.6861093 | J15: 1.693131 | L15: 1.6120678 | N15: 1.5989555 | P15: 1.6167143 | R15: 1.7395042
B73: 03
B74: 25
B75: 29
B76: 5.2740250689655177
B77: 0
B78: 0
B82: 02
B83: 2
B84: 2
B85: 5.029166
B86: 0
B87: 0
B91: 01
B92: 1
B93: 1
B94: 5.042405
B95: 0
B96: 0
B100: 03
B101: 1
B102: 1
B103: 4.760844
B104: 0
B105: 0
B109: 01
B110: 1
...

Sheet sesionIntrest
A1: BRANDINGINTEREST | B1: SESSIONS
A2: Banking & Finance/Avid Investors | B2: 107763
A3: Technology/Technophiles | B3: 89139
A4: News & Politics/Avid News Readers/Entertainment News Enthusiasts | B4: 87759
A5: Sports & Fitness/Sports Fans/Cricket Enthusiasts | B5: 85119
A6: Media & Entertainment/Movie Lovers/Fans of South Asian Film | B6: 83474
A7: Travel/Travel Buffs | B7: 81083
A8: News & Politics/Avid News Readers | B8: 78930
A9: News & Politics/Avid News Readers/Avid Business News Readers | B9: 78537
A10: Vehicles & Transportation/Auto Enthusiasts | B10: 72882
A11: Technology/Mobile Enthusiasts | B11: 70978
A12: Lifestyles & Hobbies/Shutterbugs | B12: 51982
A13: News & Politics/Avid News Readers/Avid Political News Readers | B13: 49232
... A16: Sports & Fitness/Sports Fans | B16: 35155
B22: =

Sheet networkReferral
A1: SOCIAL NETWORK | B1: VISITS | C1: PAGE VIEWS | D1: PAGES / VISITS
A2: facebook | B2: 1175 | C2: 1584 | D2: 1.3480851
A3: instagram | B3: 504 | C3: 1565 | D3: 3.1051587
A4: t.co / referral | B4: 229 | C4: 396 | D4: 1.7292576
A5: bit.ly / referral | B5: 43 | C5: 49 | D5: 1.1395349
A6: linkedin | B6: 26 | C6: 44 | D6: 1.6923077
A7: tripadvisor.com / referral | B7: 2 | C7: 3 | D7: 1.5
A8: pinterest | B8: 2 | C8: 2 | D8: 1
A9: snapchat.com / referral | B9: 1 | C9: 1 | D9: 1
A10: yourcarwala.blogspot.com / referral | B10: 1 | C10: 1 | D10: 1
A11: tripadvisor.com.my / referral | B11: 1 | C11: 1 | D11: 1

Sheet kpi-montly&year
A1: https://analytics.google.com/analytics/web/?utm_source=marketingplatform.google.com&utm_medium=et&utm_campaign=marketingplatform.google.com%2Fabout%2Fanalytics%2F#/p353077807/reports/explorer?params=_u..nav%3Dmaui%26_u.comparisonOption%3Ddisabled%26_u.date00%3D20240901%26_u.date01%3D20240930%26_r..dataFilters%3D%5B%7B%22type%22:1,%22fieldName%22:%22unifiedPagePathScreen%22,%22evaluationType%22:8,%22expressionList%22:%5B%22%252Fshowroom%252Finnova%252F%22,%22%252F%22,%22%252Fshowroom%252Furbancruiser-hyryder%252F%22,%22%252Fshowroom%252Frumion%252F%22,%22%252Fshowroom%252Furbancruiser-taisor%252F%22,%22%252Fshowroom%252Ffortuner%252Findex-fortuner.html%22,%22%252Fshowroom%252Finnova-crysta%252F%22,%22%252Fshowroom%252Fglanza%252F%22,%22%252Fshowroom%252Fhilux%252F%22,%22%252Fshowroom%252Ffortuner%252Findex-legender.html%22,%22%252Fshowroom%252Fcamry%252F%22,%22%252Fshowroom%252Fvellfire%252F%22,%22%252Fshowroom%252Flc300%252F%22,%22%252Ftoyota-in-india%252Fdelivery-lead-time%252F%22,%22%252Fmobility-solutions%252F%22%5D,%22complement%22:false,%22isCaseSensitive%22:true,%22expression%22:%22%22%7D%5D%26_r.explorerCard..startRow%3D0%26_r.explorerCard..rowsPerPage%3D25&r=6510807527&ruid=all-pages-and-screens,life-cycle,engagement&collectionId=6342606963
A4: Sl. No. | B4: Pages | C4: Avg. Load Time | D4: Bounce Rate | E4: Time Spent | F4: Total Pageviews | G4: Per day Avg | H4: Total Unique Pageviews | I4: Per day Avg.
A5: 1 | B5: Overall Website (Avg) | C5: 6.8 | D5: 0.5619 | E5: 0.0014236111 | F5: 5582723 | G5: =Table1879101112131415161718192021222324252627282930313233343536373839404142434448495152535455565758596263646568697071[[#This Row],[Total Pageviews]]/30 -> 186090.77 | H5: 2721899 | I5: =Table1879101112131415161718192021222324252627282930313233343536373839404142434448495152535455565758596263646568697071[[#This Row],[Total Unique Pageviews]]/30 -> 90729.967
A6: 2 | B6: Home Page | C6: 4.8 | D6: =TEXT(B25*100, "0.00") & "%" -> 15.51% | E6: =TEXT(INT(C25/3600), "00") & ":" & TEXT(INT(MOD(C25, 3600)/60), "00") & ":" & TEXT(MOD(C25, 60), "00") -> 00:01:16 | F6: 448494 | G6: =Table1879101112131415161718192021222324252627282930313233343536373839404142434448495152535455565758596263646568697071[[#This Row],[Total Pageviews]]/30 -> 14949.8 | H6: 247711 | I6: =Table1879101112131415161718192021222324252627282930313233343536373839404142434448495152535455565758596263646568697071[[#This Row],[Total Unique Pageviews]]/30 -> 8257.0333
A7: 3 | B7: Product Pages (Avg) | C7: 7.6 | D7: 0.3368 | E7: =TEXT(INT(C40/3600), "00") & ":" & TEXT(INT(MOD(C40, 3600)/60), "00") & ":" & TEXT(MOD(C40, 60), "00") -> 00:01:49 | F7: =AVERAGE(F8:F19) -> 280307.92 | G7: =Table1879101112131415161718192021222324252627282930313233343536373839404142434448495152535455565758596263646568697071[[#This Row],[Total Pageviews]]/30 -> 9343.5972 | H7: =AVERAGE(H8:H19) -> 204240 | I7: =Table1879101112131415161718192021222324252627282930313233343536373839404142434448495152535455565758596263646568697071[[#This Row],[Total Unique Pageviews]]/30 -> 6808
A8: 3.1 | B8: Camry | C8: 9 | D8: =TEXT(B26*100, "0.00") & "%" -> 11.96% | E8: =TEXT(INT(C26/3600), "00") & ":" & TEXT(INT(MOD(C26, 3600)/60), "00") & ":" & TEXT(MOD(C26, 60), "00") -> 00:01:44 | F8: 38649 | G8: =Table1879101112131415161718192021222324252627282930313233343536373839404142434448495152535455565758596263646568697071[[#This Row],[Total Pageviews]]/30 -> 1288.3 | H8: 28688 | I8: =Table1879101112131415161718192021222324252627282930313233343536373839404142434448495152535455565758596263646568697071[[#This Row],[Total Unique Pageviews]]/30 -> 956.26667
A9: 3.2 | B9: Fortuner | C9: 8.9 | D9: =TEXT(B27*100, "0.00") & "%" -> 48.45% | E9: =TEXT(INT(C27/3600), "00") & ":" & TEXT(INT(MOD(C27, 3600)/60), "00") & ":" & TEXT(MOD(C27, 60), "00") -> 00:01:13 | F9: 231412 | G9: =Table1879101112131415161718192021222324252627282930313233343536373839404142434448495152535455565758596263646568697071[[#This Row],[Total Pageviews]]/30 -> 7713.7333 | H9: 174732 | I9: =Table1879101112131415161718192021222324252627282930313233343536373839404142434448495152535455565758596263646568697071[[#This Row],[Total Unique Pageviews]]/30 -> 5824.4
A10: 3.3 | B10: Legender | C10: 6.8 | D10: =TEXT(B28*100, "0.00") & "%" -> 9.91% | E10: =TEXT(INT(C28/3600), "00") & ":" & TEXT(INT(MOD(C28, 3600)/60), "00") & ":" & TEXT(MOD(C28, 60), "00") -> 00:01:36 | F10: 45031 | G10: =Table1879101112131415161718192021222324252627282930313233343536373839404142434448495152535455565758596263646568697071[[#This Row],[Total Pageviews]]/30 -> 1501.0333 | H10: 32702 | I10: =Table1879101112131415161718192021222324252627282930313233343536373839404142434448495152535455565758596263646568697071[[#This Row],[Total Unique Pageviews]]/30 -> 1090.0667
A11: 3.4 | B11: Glanza | C11: 9.2 | D11: =TEXT(B29*100, "0.00") & "%" -> 64.03% | E11: =TEXT(INT(C29/3600), "00") & ":" & TEXT(INT(MOD(C29, 3600)/60), "00") & ":" & TEXT(MOD(C29, 60), "00") -> 00:01:13 | F11: 563690 | G11: =Table1879101112131415161718192021222324252627282930313233343536373839404142434448495152535455565758596263646568697071[[#This Row],[Total Pageviews]]/30 -> 18789.667 | H11: 432835 | I11: =Table1879101112131415161718192021222324252627282930313233343536373839404142434448495152535455565758596263646568697071[[#This Row],[Total Unique Pageviews]]/30 -> 14427.833
A12: 3.5 | B12: Hilux | C12: 7.7 | D12: =TEXT(B30*100, "0.00") & "%" -> 37.59% | E12: =TEXT(INT(C30/3600), "00") & ":" & TEXT(INT(MOD(C30, 3600)/60), "00") & ":" & TEXT(MOD(C30, 60), "00") -> 00:01:25 | F12: 183825 | G12: =Table1879101112131415161718192021222324252627282930313233343536373839404142434448495152535455565758596263646568697071[[#This Row],[Total Pageviews]]/30 -> 6127.5 | H12: 155711 | I12: =Table1879101112131415161718192021222324252627282930313233343536373839404142434448495152535455565758596263646568697071[[#This Row],[Total Unique Pageviews]]/30 -> 5190.3667
A13: 3.6 | B13: Innova Hycross | C13: 8.3 | D13: =TEXT(B31*100, "0.00") & "%" -> 26.87% | E13: =TEXT(INT(C31/3600), "00") & ":" & TEXT(INT(MOD(C31, 3600)/60), "00") & ":" & TEXT(MOD(C31, 60), "00") -> 00:03:07 | F13: 264319 | G13: =Table1879101112131415161718192021222324252627282930313233343536373839404142434448495152535455565758596263646568697071[[#This Row],[Total Pageviews]]/30 -> 8810.6333 | H13: 182457 | I13: =Table1879101112131415161718192021222324252627282930313233343536373839404142434448495152535455565758596263646568697071[[#This Row],[Total Unique Pageviews]]/30 -> 6081.9
A14: 3.7 | B14: Innova Crysta | C14: 7.8 | D14: =TEXT(B32*100, "0.00") & "%" -> 66.02% | E14: =TEXT(INT(C32/3600), "00") & ":" & TEXT(INT(MOD(C32, 3600)/60), "00") & ":" & TEXT(MOD(C32, 60), "00") -> 00:00:59 | F14: 290309 | G14: =Table1879101112131415161718192021222324252627282930313233343536373839404142434448495152535455565758596263646568697071[[#This Row],[Total Pageviews]]/30 -> 9676.9667 | H14: 242887 | I14: =Table1879101112131415161718192021222324252627282930313233343536373839404142434448495152535455565758596263646568697071[[#This Row],[Total Unique Pageviews]]/30 -> 8096.2333
A15: 3.8 | B15: LC300 | C15: 6 | D15: =TEXT(B33*100, "0.00") & "%" -> 11.56% | E15: =TEXT(INT(C33/3600), "00") & ":" & TEXT(INT(MOD(C33, 3600)/60), "00") & ":" & TEXT(MOD(C33, 60), "00") -> 00:01:46 | F15: 36637 | G15: =Table1879101112131415161718192021222324252627282930313233343536373839404142434448495152535455565758596263646568697071[[#This Row],[Total Pageviews]]/30 -> 1221.2333 | H15: 27307 | I15: =Table1879101112131415161718192021222324252627282930313233343536373839404142434448495152535455565758596263646568697071[[#This Row],[Total Unique Pageviews]]/30 -> 910.23333
A16: 3.9 | B16: Rumion | C16: 5.6 | D16: =TEXT(B34*100, "0.00") & "%" -> 11.61% | E16: =TEXT(INT(C34/3600), "00") & ":" & TEXT(INT(MOD(C34, 3600)/60), "00") & ":" & TEXT(MOD(C34, 60), "00") -> 00:03:15 | F16: 36542 | G16: =Table1879101112131415161718192021222324252627282930313233343536373839404142434448495152535455565758596263646568697071[[#This Row],[Total Pageviews]]/30 -> 1218.0667 | H16: 26669 | I16: =Table1879101112131415161718192021222324252627282930313233343536373839404142434448495152535455565758596263646568697071[[#This Row],[Total Unique Pageviews]]/30 -> 888.96667
A17: 3.1 | B17: UC Hyryder | C17: 6.7 | D17: =TEXT(B35*100, "0.00") & "%" -> 37.53% | E17: =TEXT(INT(C35/3600), "00") & ":" & TEXT(INT(MOD(C35, 3600)/60), "00") & ":" & TEXT(MOD(C35, 60), "00") -> 00:01:49 | F17: 352173 | G17: =Table1879101112131415161718192021222324252627282930313233343536373839404142434448495152535455565758596263646568697071[[#This Row],[Total Pageviews]]/30 -> 11739.1 | H17: 244231 | I17: =Table1879101112131415161718192021222324252627282930313233343536373839404142434448495152535455565758596263646568697071[[#This Row],[Total Unique Pageviews]]/30 -> 8141.0333
A18: 3.11 | B18: UC Taisor | C18: 7.3 | D18: =TEXT(B36*100, "0.00") & "%" -> 14.59% | E18: =TEXT(INT(C36/3600), "00") & ":" & TEXT(INT(MOD(C36, 3600)/60), "00") & ":" & TEXT(MOD(C36, 60), "00") -> 00:02:16 | F18: 92195 | G18: =Table1879101112131415161718192021222324252627282930313233343536373839404142434448495152535455565758596263646568697071[[#This Row],[Total Pageviews]]/30 -> 3073.1667 | H18: 57189 | I18: =Table1879101112131415161718192021222324252627282930313233343536373839404142434448495152535455565758596263646568697071[[#This Row],[Total Unique Pageviews]]/30 -> 1906.3
A19: 3.12 | B19: Vellfire | C19: 8.7 | D19: =TEXT(B37*100, "0.00") & "%" -> 64.13% | E19: =TEXT(INT(C37/3600), "00") & ":" & TEXT(INT(MOD(C37, 3600)/60), "00") & ":" & TEXT(MOD(C37, 60), "00") -> 00:01:22 | F19: 1228913 | G19: =Table1879101112131415161718192021222324252627282930313233343536373839404142434448495152535455565758596263646568697071[[#This Row],[Total Pageviews]]/30 -> 40963.767 | H19: 845472 | I19: =Table1879101112131415161718192021222324252627282930313233343536373839404142434448495152535455565758596263646568697071[[#This Row],[Total Unique Pageviews]]/30 -> 28182.4
... A21: 5 | B21: Delivery Lead Time | C21: 2.9 | D21: =TEXT(B39*100, "0.00") & "%" -> 20.01% | E21: =TEXT(INT(C39/3600), "00") & ":" & TEXT(INT(MOD(C39, 3600)/60), "00") & ":" & TEXT(MOD(C39, 60), "00") -> 00:01:55 | F21: 12025 | G21: =Table1879101112131415161718192021222324252627282930313233343536373839404142434448495152535455565758596263646568697071[[#This Row],[Total Pageviews]]/30 -> 400.83333 | H21: 9056 | I21: =Table1879101112131415161718192021222324252627282930313233343536373839404142434448495152535455565758596263646568697071[[#This Row],[Total Unique Pageviews]]/30 -> 301.86667
A24: Page path and screen class | B24: Bounce rate | C24: Average session duration | D24: Views | E24: Active users | G24: avg of product
B25: 0.1550508 | C25: 75.582028 | D25: 448494
A26: camry/ | B26: 0.11958905 | C26: 104.29218 | D26: 38649 | E26: 24018 | G26: 19.41 | H26: 11.96
A27: fortuner.html | B27: 0.48448263 | C27: 73.198863 | D27: 231412 | E27: 54859 | G27: 21.93 | H27: 48.45
A28: fortuner/index-legender.html | B28: 0.099095384 | C28: 96.07158 | D28: 45031 | E28: 23370 | G28: 16.51 | H28: 9.91
A29: glanza/ | B29: 0.64034771 | C29: 72.757911 | D29: 563690 | E29: 39291 | G29: 23.31 | H29: 64.03
A30: hilux/ | B30: 0.37586373 | C30: 84.653908 | D30: 183825 | E30: 35447 | G30: 26.83 | H30: 37.59
A31: innova/ | B31: 0.26869274 | C31: 186.51806 | D31: 264319 | E31: 146848 | G31: 42.73 | H31: 26.87
A32: innova-crysta/ | B32: 0.66024563 | C32: 59.15243 | D32: 290309 | E32: 55622 | G32: 21.65 | H32: 66.02
A33: lc300/ | B33: 0.11559586 | C33: 105.92176 | D33: 36637 | E33: 22626 | G33: 13.79 | H33: 11.56
A34: rumion/ | B34: 0.11607115 | C34: 194.55944 | D34: 36542 | E34: 28347 | G34: 12.97 | H34: 11.61
A35: urbancruiser-hyryder/ | B35: 0.37532915 | C35: 109.48365 | D35: 352173 | E35: 87350 | G35: 26.13 | H35: 37.53
A36: urbancruiser-taisor/ | B36: 0.14585016 | C36: 135.53566 | D36: 92195 | E36: 79384 | G36: 18.24 | H36: 14.59
A37: vellfire/ | B37: 0.64129149 | C37: 81.861924 | D37: 1228913 | E37: 22132 | G37: 21.01 | H37: 64.13
A38: mobility-solutions/ | B38: 0.05897772 | C38: 60.43541 | D38: 8211 | E38: 4582
A39: toyota-in-india/delivery-lead-time/ | B39: 0.20010355 | C39: 115.48268 | D39: 12025 | E39: 9056
C40: =AVERAGE(C26:C37) -> 108.66728
A45: Sl. No. | B45: Pages | C45: Bounce Rate | D45: Time Spent | E45: Total Pageviews | F45: Per day Avg | G45: Total Unique Pageviews | H45: Per day Avg.
A46: 1 | B46: Overall Website (Avg) | C46: 0.5452 | D46: 0.0016435185 | E46: 18785585 | F46: =Table18791011121314151617181920212223242526272829303132333435363738394041424344484951525354555657585962636465686970713[[#This Row],[Total Pageviews]]/181 -> 103787.76 | G46: 7522783 | H46: =Table18791011121314151617181920212223242526272829303132333435363738394041424344484951525354555657585962636465686970713[[#This Row],[Total Unique Pageviews]]/181 -> 41562.337
A47: 2 | B47: Home Page | C47: =TEXT(B69*100, "0.00") & "%" -> 26.56% | D47: =TEXT(INT(C69/3600), "00") & ":" & TEXT(INT(MOD(C69, 3600)/60), "00") & ":" & TEXT(MOD(C69, 60), "00") -> 00:01:10 | E47: 2535514 | F47: =Table18791011121314151617181920212223242526272829303132333435363738394041424344484951525354555657585962636465686970713[[#This Row],[Total Pageviews]]/181 -> 14008.365 | G47: 1482436 | H47: =Table18791011121314151617181920212223242526272829303132333435363738394041424344484951525354555657585962636465686970713[[#This Row],[Total Unique Pageviews]]/181 -> 8190.2541
A48: 3 | B48: Product Pages (Avg) | C48: 0.343 | D48: =TEXT(INT(C85/3600), "00") & ":" & TEXT(INT(MOD(C85, 3600)/60), "00") & ":" & TEXT(MOD(C85, 60), "00") -> 00:01:49 | E48: =AVERAGE(E49:E60) -> 823915.58 | F48: =Table18791011121314151617181920212223242526272829303132333435363738394041424344484951525354555657585962636465686970713[[#This Row],[Total Pageviews]]/181 -> 4552.0198 | G48: =AVERAGE(G49:G60) -> 549402.75 | H48: =Table18791011121314151617181920212223242526272829303132333435363738394041424344484951525354555657585962636465686970713[[#This Row],[Total Unique Pageviews]]/181 -> 3035.3743
A49: 3.1 | B49: Camry | C49: =TEXT(B70*100, "0.00") & "%" -> 61.79% | D49: =TEXT(INT(C70/3600), "00") & ":" & TEXT(INT(MOD(C70, 3600)/60), "00") & ":" & TEXT(MOD(C70, 60), "00") -> 00:01:07 | E49: 1650045 | F49: =Table18791011121314151617181920212223242526272829303132333435363738394041424344484951525354555657585962636465686970713[[#This Row],[Total Pageviews]]/181 -> 9116.2707 | G49: 883450 | H49: =Table18791011121314151617181920212223242526272829303132333435363738394041424344484951525354555657585962636465686970713[[#This Row],[Total Unique Pageviews]]/181 -> 4880.9392
...

Sheet Dealer-Website
A1: Dealership | B1: Visits
A2: Ravindu Toyota | B2: 19843
A3: Millennium Toyota | B3: 15560
A4: Uttam Toyota | B4: 15256
A5: Nippon Toyota | B5: 14535
A6: Amana Toyota | B6: 9640
A7: Nandi Toyota | B7: 8309
A8: Harsha Toyota | B8: 7741
A9: Lanson Toyota | B9: 7534
A10: Anaamalais Toyota Trichy | B10: 7417
A11: Viva Toyota | B11: 6283
A12: Budha Toyota | B12: 4750
A13: Topsel Toyota | B13: 4289
... A18: Anaamalais Toyota | B18: 3015
A19: Shodha Toyota
A20: Uttam Toyota
A21: Madhuban Toyota
A22: Sharayu Toyota
A23: Topsel Toyota
A24: Shaw Toyota
A25: Rajendra Toyota
A26: Rajendra Toyota
A27: Sonak Toyota
A28: Anaamalais Toyota
A29: Anaamalais Toyota
A30: Wasan Toyota
... A112: Autowings Toyota
