Workbook

Sheet tbltransaction-organic
A1: Month | B1: Innova Crysta | C1: Camry | D1: Fortuner | E1: Legender | F1: Vellfire | G1: Innova Hycross | H1: Hilux | I1: Glanza | J1: Urban Cruiser Hyryder | K1: Urban Cruiser Taisor | L1: Land Cruiser 300 | M1: Rumion
A2: Mar 2025 | B2: 553 | C2: 239 | D2: 552 | E2: 248 | F2: 41 | G2: 1231 | H2: 278 | I2: 401 | J2: 1118 | K2: 525 | L2: 126 | M2: 304
A3: Apr 2025 | B3: 461 | C3: 197 | D3: 535 | E3: 238 | F3: 61 | G3: 1260 | H3: 195 | I3: 386 | J3: 1137 | K3: 495 | L3: 118 | M3: 250
A4: May 2025 | B4: 378 | C4: 191 | D4: 493 | E4: 233 | F4: 145 | G4: 1160 | H4: 178 | I4: 396 | J4: 1124 | K4: 433 | L4: 110 | M4: 236
A5: Jun 2025 | B5: 414 | C5: 185 | D5: 637 | E5: 245 | F5: 463 | G5: 1157 | H5: 170 | I5: 458 | J5: 1061 | K5: 439 | L5: 100 | M5: 236
A6: Jul 2025 | B6: 414 | C6: 220 | D6: 584 | E6: 257 | F6: 263 | G6: 1046 | H6: 180 | I6: 491 | J6: 1132 | K6: 466 | L6: 342 | M6: 217
A7: Aug 2025 | B7: 455 | C7: 187 | D7: 518 | E7: 247 | F7: 123 | G7: 1003 | H7: 205 | I7: 460 | J7: 1084 | K7: 477 | L7: 830 | M7: 218
A8: Sep 2025 | B8: 597 | C8: 175 | D8: 608 | E8: 278 | F8: 98 | G8: 1182 | H8: 241 | I8: 483 | J8: 1237 | K8: 721 | L8: 417 | M8: 215 | N8: =SUM(B8:M8)
A9: Total(model-wise) | B9: =SUM(B2:B8) | C9: =SUM(C2:C8) | D9: =SUM(D2:D8) | E9: =SUM(E2:E8) | F9: =SUM(F2:F8) | G9: =SUM(G2:G8) | H9: =SUM(H2:H8) | I9: =SUM(I2:I8) | ... M9: =SUM(M2:M8)

Sheet tbltransaction-paid
A1: Month | B1: Innova Crysta | C1: Camry | D1: Fortuner | E1: Legender | F1: Vellfire | G1: Innova Hycross | H1: Hilux | I1: Glanza | J1: Urban Cruiser Hyryder | K1: Urban Cruiser Taisor | L1: Land Cruiser 300 | M1: Rumion
A2: Mar 2025 | B2: 3666 | C2: 2889 | D2: 4511 | E2: 9 | F2: 4 | G2: 99 | H2: 4405 | I2: 32286 | J2: 35553 | K2: 32401 | L2: 7 | M2: 12
A3: Apr 2025 | B3: 2238 | C3: 483 | D3: 2982 | E3: 10 | F3: 3 | G3: 80 | H3: 2597 | I3: 7364 | J3: 26545 | K3: 12177 | L3: 18 | M3: 9
A4: May 2025 | B4: 983 | C4: 4048 | D4: 21 | E4: 6 | F4: 675 | G4: 2198 | H4: 5243 | I4: 28472 | J4: 34930 | K4: 18748 | L4: 7 | M4: 12
A5: Jun 2025 | B5: 4415 | C5: 4524 | D5: 3049 | E5: 21 | F5: 2707 | G5: 3613 | H5: 5297 | I5: 32974 | J5: 33303 | K5: 18437 | L5: 11 | M5: 8
A6: Jul 2025 | B6: 32 | C6: 3130 | D6: 1739 | E6: 2882 | F6: 1433 | G6: 4913 | H6: 5337 | I6: 41708 | J6: 34248 | K6: 12111 | L6: 632 | M6: 8
A7: Aug 2025 | B7: 2415 | C7: 3616 | D7: 201 | E7: 2881 | F7: 2149 | G7: 4148 | H7: 6111 | I7: 37094 | J7: 45498 | K7: 15442 | L7: 1588 | M7: 13
A8: Sep 2025 | B8: 7723 | C8: 4662 | D8: 41 | E8: 4329 | F8: 2525 | G8: 5490 | H8: 5800 | I8: 40908 | J8: 51184 | K8: 18184 | L8: 1382 | M8: 10
A9: Total (model-wise) | B9: =SUM(B2:B8) | C9: =SUM(C2:C8) | D9: =SUM(D2:D8) | E9: =SUM(E2:E8) | F9: =SUM(F2:F8) | G9: =SUM(G2:G8) | H9: =SUM(H2:H8) | I9: =SUM(I2:I8) | ... M9: =SUM(M2:M8)

Sheet users-and-bounce-rate
B1: 164624 | C1: 1111867 | D1: 141411 | E1: 758418 | F1: 154087 | G1: 863230 | H1: 153524 | I1: 681472 | J1: 175598 | K1: 931043 | L1: 248232 | M1: 2509236
B2: -0.13 | C2: -0.87 | D2: -0.1558 | E2: -0.8357 | F2: -0.1505 | G2: -0.8432 | H2: -0.183 | I2: -0.8124 | J2: -0.1579 | K2: -0.8373 | L2: -0.0899 | M2: -0.9087
B3: 0.2439 | C3: 0.6168 | D3: 0.2519 | E3: 0.5689 | F3: 0.2502 | G3: 0.5414 | H3: 0.2389 | I3: 0.5086 | J3: 0.2419 | K3: 0.4352 | L3: 0.2807 | M3: 0.5982
A9: Months | B9: 45658 | D9: 45689 | F9: 45717 | H9: 45748 | J9: 45778 | L9: 45809
A10: Device | B10: Desktop Users | C10: Mobile Users | D10: Desktop Users | E10: Mobile Users | F10: Desktop Users | G10: Mobile Users | H10: Desktop Users | I10: Mobile Users | J10: Desktop Users | K10: Mobile Users | L10: Desktop Users | M10: MobileUsers
A11: Users | B11: =B1 & CHAR(10) & "(" &(-1*B2)*100 & "%)" | C11: =C1 & CHAR(10) & "(" &(-1*C2)*100 & "%)" | D11: =D1 & CHAR(10) & "(" &(-1*D2)*100 & "%)" | E11: =E1 & CHAR(10) & "(" &(-1*E2)*100 & "%)" | F11: =F1 & CHAR(10) & "(" &(-1*F2)*100 & "%)" | G11: =G1 & CHAR(10) & "(" &(-1*G2)*100 & "%)" | H11: =H1 & CHAR(10) & "(" &(-1*H2)*100 & "%)" | I11: =I1 & CHAR(10) & "(" &(-1*I2)*100 & "%)" | ... M11: =M1 & CHAR(10) & "(" &(-1*M2)*100 & "%)"
A12: Bounce Rate | B12: 0.2439 | C12: 0.6168 | D12: 0.2519 | E12: 0.5689 | F12: 0.2502 | G12: 0.5414 | H12: 0.2389 | I12: 0.5086 | J12: 0.2419 | K12: 0.4352 | L12: 0.2807 | M12: 0.5982

Sheet productsbouncerate
B1: Bounce Rate | C1: views | D1: Percentage | E1: Final output
A2: /Showroom/fortuner/index-legender.html | B2: 50.00% | C2: 12 | D2: =C2/$C$19 | E2: =TEXT(C2, "0") & CHAR(10) &"("& TEXT(D2, "0.00%")&")"
A3: /showroom/Glanza/ | B3: 0.00% | C3: 1 | D3: =C3/$C$19 | E3: =TEXT(C3, "0") & CHAR(10) &"("& TEXT(D3, "0.00%")&")"
A4: /showroom/Innova/ | B4: 0.00% | C4: 2 | D4: =C4/$C$19 | E4: =TEXT(C4, "0") & CHAR(10) &"("& TEXT(D4, "0.00%")&")"
A5: /showroom/Rumion/ | B5: 70.00% | C5: 12 | D5: =C5/$C$19 | E5: =TEXT(C5, "0") & CHAR(10) &"("& TEXT(D5, "0.00%")&")"
A6: /showroom/UrbanCruiser-hyryder/ | B6: 0.00% | C6: 2 | D6: =C6/$C$19 | E6: =TEXT(C6, "0") & CHAR(10) &"("& TEXT(D6, "0.00%")&")"
A7: /showroom/camry/ | B7: 68.60% | C7: 435656 | D7: =C7/$C$19 | E7: =TEXT(C7, "0") & CHAR(10) &"("& TEXT(D7, "0.00%")&")"
A8: /showroom/fortuner/index-fortuner.html | B8: 36.04% | C8: 169366 | D8: =C8/$C$19 | E8: =TEXT(C8, "0") & CHAR(10) &"("& TEXT(D8, "0.00%")&")"
A9: /showroom/fortuner/index-legender.html | B9: 14.71% | C9: 42240 | D9: =C9/$C$19 | E9: =TEXT(C9, "0") & CHAR(10) &"("& TEXT(D9, "0.00%")&")"
A10: /showroom/glanza/ | B10: 41.69% | C10: 116117 | D10: =C10/$C$19 | E10: =TEXT(C10, "0") & CHAR(10) &"("& TEXT(D10, "0.00%")&")"
A11: /showroom/hilux/ | B11: 18.30% | C11: 43786 | D11: =C11/$C$19 | E11: =TEXT(C11, "0") & CHAR(10) &"("& TEXT(D11, "0.00%")&")"
A12: /showroom/innova-Crysta/ | B12: 57.14% | C12: 7 | D12: =C12/$C$19 | E12: =TEXT(C12, "0") & CHAR(10) &"("& TEXT(D12, "0.00%")&")"
A13: /showroom/innova-crysta/ | B13: 21.86% | C13: 104335 | D13: =C13/$C$19 | E13: =TEXT(C13, "0") & CHAR(10) &"("& TEXT(D13, "0.00%")&")"
A14: /showroom/innova/ | B14: 15.68% | C14: 135563
A15: /showroom/lc300/ | B15: 21.62% | C15: 59918
A16: /showroom/rumion/ | B16: 14.36% | C16: 36107
A17: /showroom/urbancruiser-hyryder/ | B17: 50.61% | C17: 434357
A18: /showroom/urbancruiser-taisor/ | B18: 13.97% | C18: 103956
A19: /showroom/vellfire/ | B19: 63.26% | C19: 273093

Sheet Site - Month Graph
C1: Page Views
C3: Date(mm/dd/yyyy) | D3: Page Views(Overall) | E3: Page Views(Mobile)
C4: 01-10-2025 | D4: 126565 | E4: 97703
C5: 02-10-2025 | D5: 130057 | E5: 106679
C6: 03-10-2025 | D6: 138605 | E6: 107562
C7: 04-10-2025 | D7: 142086 | E7: 111731
C8: 05-10-2025 | D8: 135770 | E8: 114163
C9: 06-10-2025 | D9: 147871 | E9: 113322
C10: 07-10-2025 | D10: 138958 | E10: 107444
C11: 08-10-2025 | D11: 131119 | E11: 98620
C12: 09-10-2025 | D12: 128450 | E12: 96686
C13: 10-10-2025 | D13: 125979 | E13: 96091
C14: 11-10-2025 | D14: 121732 | E14: 95271
C15: 12-10-2025 | D15: 116690 | E15: 95292
... C33: 30-10-2025 | D33: 117554 | E33: 89681
C34: 31-10-2025 | D34: 113514 | E34: 87906 | H34: =D35 & " pages has been viewed overall, average page view per day is " & D36 & ". Page views - lowest on " & TEXT(D38, "dddd, mmmm dd") & IF(OR(DAY(D38)=1, DAY(D38)=21, DAY(D38)=31), "st", IF(OR(DAY(D38)=2, DAY(D38)=22), "nd", IF(OR(DAY(D38)=3, DAY(D38)=23), "rd", "th"))) & ", " & TEXT(D38, "yyyy") & " (" & D37 & "). " & E35 & " pages has been viewed only on mobile, average page view per day is " & E36 & ". Page views - lowest on " & TEXT(E38, "dddd, mmmm dd") & IF(OR(DAY(E38)=1, DAY(E38)=21, DAY(E38)=31), "st", IF(OR(DAY(E38)=2, DAY(E38)=22), "nd", IF(OR(DAY(E38)=3, DAY(E38)=23), "rd", "th"))) & ", " & TEXT(E38, "yyyy") & " (" & E37 & ")."
C35: Totall | D35: =SUM(D4:D34) | E35: =SUM(E4:E34)
C36: Average per day | D36: =ROUND(AVERAGE(D4:D34),0) | E36: =ROUND(AVERAGE(E4:E34),0)
C37: lowest | D37: =MIN(D4:D34) | E37: =MIN(E4:E34)
C38: lowest On | D38: =INDEX(C4:C34,MATCH(MIN(D4:D34),D4:D34,0)) | E38: =INDEX(C4:C34,MATCH(MIN(E4:E34),E4:E34,0))
C42: Unique Visit
C44: Date(mm/dd/yyyy) | D44: Unique Visit(Overall) | E44: Unique Visit(Mobile)
C45: 01-10-2025 | D45: 52183 | E45: 45356
C46: 02-10-2025 | D46: 55606 | E46: 49077
C47: 03-10-2025 | D47: 59125 | E47: 51027
C48: 04-10-2025 | D48: 59705 | E48: 52729
C49: 05-10-2025 | D49: 58354 | E49: 52795
C50: 06-10-2025 | D50: 64107 | E50: 55545
C51: 07-10-2025 | D51: 59707 | E51: 52016
C52: 08-10-2025 | D52: 53775 | E52: 45619
C53: 09-10-2025 | D53: 51910 | E53: 44003
C54: 10-10-2025 | D54: 51778 | E54: 44240
C55: 11-10-2025 | D55: 48925 | E55: 42716
C56: 12-10-2025 | D56: 47080 | E56: 41834
... C75: 31-10-2025 | D75: 47933 | E75: 41991
D76: =SUM(D45:D75) | E76: =SUM(E45:E75)
D77: =ROUND(AVERAGE(D45:D75),0) | E77: =ROUND(AVERAGE(E45:E75),0)

Sheet No of Visitors
A1: Date | B1: Visits | C1: Date | D1: Visits
A2: May-2025 | B2: 1386083 | C2: May-2025 | D2: 1127700
A3: Jun-2025 | B3: 3436416 | C3: Jun-2025 | D3: 3122151
A4: Jul-2025 | B4: 4167538 | C4: Jul-2025 | D4: 3844822
A5: Aug-2025 | B5: 1883860 | C5: Aug-2025 | D5: 1585494
A6: Sep-2025 | B6: 2306319 | C6: Sep-2025 | D6: 1941298
A7: Oct-2025 | B7: 2295204 | C7: Oct-2025 | D7: 1903070
K32: OVERALL | W32: MOBILE

Sheet Online Requests Trends
A1: Month_Year | B1: Lead
A2: Apr-2025 | B2: 59939 | E2: Requests | F2: %
A3: May-2025 | B3: 100509 | D3: Brochure | E3: 81 | F3: =(E3/E7)*100
A4: Jun-2025 | B4: 114024 | D4: Buy Now | E4: 132338 | F4: =(E4/E7)*100
A5: Jul-2025 | B5: 113905 | D5: Grievance | E5: 126 | F5: =(E5/E7)*100
A6: Aug-2025 | B6: 127069 | D6: Test Drive | E6: 16071 | F6: =(E6/E7)*100
A7: Sep-2025 | B7: 148616 | D7: Total | E7: =SUM(E3:E6) | F7: =SUM(F3:F6)
B14: ="Total Requests: " & E7 & " NOS."
B15: Enquiry:-
B16: =D4&" : " & E4 & " (" & TEXT(F4, "0.00") & "%)" | C16: =D3&" " & E3 & " (" & TEXT(F3, "0.00") & "%)"
B18: =D5&" : " & E5 & " (" & TEXT(F5, "0.00") & "%)" | C18: =D6&": " & E6 & " (" & TEXT(F6, "0.00") & "%)"

Sheet Brochure And FlipBook Counts
A1: Car Chapters | B1: Brochure Downloaded Clicks | C1: Car Chapter View Brochure | D1: Flipbook Clicks | E1: Download Brochure Page Views
A2: Download Brochure - Urban Cruiser Hyryder | B2: 85543 | C2: - | D2: 112849 | E2: 267924
A3: Download Brochure - Innova Hycross | B3: 56019 | C3: 3411
A4: Download Brochure - Glanza | B4: 26760 | C4: -
A5: Download Brochure - Urban Cruiser Taisor | B5: 25664 | C5: 6050
A6: Download Brochure - Vellfire | B6: 17783 | C6: -
A7: Download Brochure - Hilux | B7: 14915 | C7: -
A8: Download Brochure - Land Cruiser 300 | B8: 14673 | C8: -
A9: Download Brochure - Camry | B9: 13433 | C9: 8677
A10: Download Brochure - Rumion | B10: 10007 | C10: 3599
A11: Download Brochure - Fortuner | B11: 4072 | C11: 17612
A12: Download Brochure - Innova Crysta | B12: 3789 | C12: 7584
A13: Download Brochure - Legender | B13: 2519 | C13: 7185
A24: https://analytics.google.com/analytics/web/?authuser=0#/p353077807/reports/explorer?params=_u..nav%3Dmaui%26_u.comparisonOption%3Ddisabled%26_u.date00%3D20250101%26_u.date01%3D20250630%26_r..dataFilters%3D%5B%7B%22type%22:1,%22fieldName%22:%22customDimensionsGroup2Slot06%22,%22evaluationType%22:8,%22expressionList%22:%5B%22Download%20Brochure%20-%20Urban%20Cruiser%20Hyryder%22,%22Download%20Brochure%20-%20Innova%20Hycross%22,%22Download%20Brochure%20-%20Urban%20Cruiser%20Taisor%22,%22Download%20Brochure%20-%20Vellfire%22,%22Download%20Brochure%20-%20Hilux%22,%22Download%20Brochure%20-%20Land%20Cruiser%20300%22,%22Download%20Brochure%20-%20Rumion%22,%22Download%20Brochure%20-%20Camry%22,%22Download%20Brochure%20-%20Fortuner%22,%22Download%20Brochure%20-%20Innova%20Crysta%22,%22Download%20Brochure%20-%20Legender%22%5D,%22complement%22:false,%22isCaseSensitive%22:true,%22expression%22:%22%22%7D%5D%26_r.copa-filter-builder..filter-to-edit%3D%5B%7B%22type%22:1,%22fieldName%22:%22customDimensionsGroup2Slot06%22,%22evaluationType%22:8,%22expressionList%22:%5B%22Download%20Brochure%20-%20Urban%20Cruiser%20Hyryder%22,%22Download%20Brochure%20-%20Innova%20Hycross%22,%22Download%20Brochure%20-%20Urban%20Cruiser%20Taisor%22,%22Download%20Brochure%20-%20Vellfire%22,%22Download%20Brochure%20-%20Hilux%22,%22Download%20Brochure%20-%20Land%20Cruiser%20300%22,%22Download%20Brochure%20-%20Rumion%22,%22Download%20Brochure%20-%20Camry%22,%22Download%20Brochure%20-%20Fortuner%22,%22Download%20Brochure%20-%20Innova%20Crysta%22,%22Download%20Brochure%20-%20Legender%22%5D,%22complement%22:false,%22isCaseSensitive%22:true,%22expression%22:%22%22%7D%5D%26_r.explorerCard..seldim%3D%5B%22eventName%22,%22customDimensionsGroup2Slot06%22%5D%26_r.explorerCard..startRow%3D0%26_r.explorerCard..rowsPerPage%3D25&ruid=top-events,life-cycle,engagement&collectionId=6342606963&r=7537197290
A27: Car Chapters | B27: Brochure Downloaded Clicks label name | C27: Car Chapter View Brochure
A28: Glanza | B28: Download Brochure - Glanza | C28: View B
A29: Urban Cruiser Taisor | B29: Download Brochure - Urban Cruiser Taisor | D29: Urban Cruiser Taisor
A30: Rumion | B30: Download Brochure - Rumion | D30: Rumion Tab
A31: Urban Cruiser Hyryder | B31: Download Brochure - Urban Cruiser Hyryder
A32: Innova Crysta | B32: Download Brochure - Innova Crysta | D32: Innova Crysta
A33: Innova Hycross | B33: Download Brochure - Innova Hycross
A34: Hilux | B34: Download Brochure - Hilux
A35: Fortuner | B35: Download Brochure - Fortuner | D35: New Fortuner Tab
A36: Legender | B36: Download Brochure - Legender | D36: Legender Tab
A37: Camry | B37: Download Brochure - Camry | D37: Camry
A38: Vellfire | B38: Download Brochure - Vellfire
A39: Land Cruiser 300 | B39: Download Brochure - Land Cruiser 300

Sheet virtualshowroom
A1: Virtual Showroom Car Chapters | B1: Sessions | C1: Page Views | D1: Avg Time Spent
A2: /virtual-showroom/ | B2: 135347 | C2: 155657 | D2: 1m 59s
A3: /virtual-showroom/urbancruisertaisor.html | B3: 30628 | C3: 38356 | D3: 4m 15s
A4: /virtual-showroom/urbancruiserhyryder.html | B4: 25714 | C4: 30878 | D4: 5m 15s
A5: /virtual-showroom/innova.html | B5: 25232 | C5: 30125 | D5: 5m 08s
A6: /virtual-showroom/lc300.html | B6: 18845 | C6: 23574 | D6: 2m 35s
A7: /virtual-showroom/camry.html | B7: 18365 | C7: 21777 | D7: 2m 51s
A8: /virtual-showroom/fortuner.html | B8: 17828 | C8: 23742 | D8: 3m 55s
A9: /virtual-showroom/legender.html | B9: 12238 | C9: 15565 | D9: 3m 35s
A10: /virtual-showroom/vellfire.html | B10: 11499 | C10: 13580 | D10: 2m 27s
A11: /virtual-showroom/innovacrysta.html | B11: 11040 | C11: 13368 | D11: 5m 09s
A12: /virtual-showroom/glanza.html | B12: 10259 | C12: 12114 | D12: 4m 29s
A13: /virtual-showroom/hilux.html | B13: 5304 | C13: 6576 | D13: 3m 34s
... A16: /virtual-showroom/index.html | B16: 4 | C16: 6 | D16: 41s
A20: Virtual Showroom Car Chapters | B20: Sessions | C20: Page Views | D20: Avg Time Spent
A21: /virtual-showroom/ | B21: 504414 | C21: 631636 | D21: 2m 38s
A22: /virtual-showroom/urbancruisertaisor.html | B22: 235710 | C22: 292095 | D22: 3m 57s
A23: /virtual-showroom/camry.html | B23: 222893 | C23: 268207 | D23: 2m 39s
A24: /virtual-showroom/urbancruiserhyryder.html | B24: 201948 | C24: 246225 | D24: 5m 09s
A25: /virtual-showroom/glanza.html | B25: 186865 | C25: 217045 | D25: 2m 53s
A26: /virtual-showroom/innova.html | B26: 186486 | C26: 230664 | D26: 5m 17s
A27: /virtual-showroom/lc300.html | B27: 150458 | C27: 179254 | D27: 2m 13s
A28: /virtual-showroom/fortuner.html | B28: 130802 | C28: 176496 | D28: 4m 08s
A29: /virtual-showroom/vellfire.html | B29: 107804 | C29: 130244 | D29: 2m 26s
A30: /virtual-showroom/legender.html | B30: 105622 | C30: 133640 | D30: 3m 03s
A31: /virtual-showroom/hilux.html | B31: 85390 | C31: 97763 | D31: 2m 23s
A32: /virtual-showroom/innovacrysta.html | B32: 66738 | C32: 83097 | D32: 4m 57s
... A35: /virtual-showroom/Innova.html | B35: 126 | C35: 159 | D35: 3m 30s

Sheet Section Performance
B1: Mothly
A3: S.No | B3: Page path | C3: Pageviews | D3: Percentage | E3: Unique Pageviews | F3: Percentage
A4: 1 | B4: /showroom/camry/ | C4: 435656 | D4: =C4 / $C$14 | E4: 302774 | F4: =E4 / $E$14
A5: 2 | B5: /showroom/urbancruiser-hyryder/ | C5: 434357 | D5: =C5 / $C$14 | E5: 242167 | F5: =E5 / $E$14
A6: 3 | B6: / | C6: 431338 | D6: =C6 / $C$14 | E6: 199590 | F6: =E6 / $E$14
A7: 4 | B7: /showroom/vellfire/ | C7: 273093 | D7: =C7 / $C$14 | E7: 152929 | F7: =E7 / $E$14
A8: 5 | B8: /campaign/urbancruiser-hyryder/ | C8: 220319 | D8: =C8 / $C$14 | E8: 148703 | F8: =E8 / $E$14
A9: 6 | B9: /pricelist/ | C9: 198608 | D9: =C9 / $C$14 | E9: 16518 | F9: =E9 / $E$14 | U9: / | V9: 3641104 | W9: 2065856
A10: 7 | B10: /showroom/fortuner/index-fortuner.html | C10: 169366 | D10: =C10 / $C$14 | E10: 76013 | F10: =E10 / $E$14 | U10: /showroom/glanza/ | V10: 3627783 | W10: 2578524
A11: 8 | B11: /showroom/innova/ | C11: 135563 | D11: =C11 / $C$14 | E11: 42030 | F11: =E11 / $E$14 | U11: /showroom/urbancruiser-taisor/ | V11: 3046568 | W11: 2061639
A12: 9 | B12: /showroom/glanza/ | C12: 116117 | D12: =C12 / $C$14 | E12: 54567 | F12: =E12 / $E$14 | U12: /showroom/camry/ | V12: 2590701 | W12: 1196886
A13: 10 | B13: /showroom/innova-crysta/ | C13: 104335 | D13: =C13 / $C$14 | E13: 35774 | F13: =E13 / $E$14 | U13: /showroom/urbancruiser-hyryder/ | V13: 1893051 | W13: 1142366
C14: 3953609 | D14: =SUM(D4:D13) | E14: 1673657 | F14: =SUM(F4:F13) | U14: /showroom/innova/ | V14: 1560879 | W14: 981618
U15: /campaign/glanza/index.html | V15: 1258673 | W15: 803479
U16: /showroom/fortuner/index-fortuner.html | V16: 976564 | W16: 668485
A17: =" - Top 10 sections constitute " & TEXT(D14, "0.00%") & " of Page views. (Total Page views – " & TEXT(C14, "#,##0") & ")" & CHAR(10) & " - " & TEXT(F14, "0.00%") & " of page views are unique Page views for top 10 sections." | B17: /showroom/urbancruiser-taisor/ | C17: 92195 | E17: 16446 | U17: /pricelist/ | V17: 859398 | W17: 517912
B18: /campaign/glanza/index.html | C18: 84553 | E18: 72113 | U18: /showroom/innova-crysta/ | V18: 822530 | W18: 564497
B25: YEAR TO TILL
A27: S.No | B27: Page path | C27: Pageviews | D27: Percentage | E27: Unique Pageviews | F27: Percentage | T27: Toyota Camry | U27: 2542304 | V27: 48384 | W27: =SUM(U27:V27)
A28: 1 | B28: / | C28: 4354608 | D28: =C28/ $C$38 | E28: 2059610 | F28: =E28 / $E$38 | T28: Toyota Fortuner | U28: 896824 | V28: 111688 | W28: =SUM(U28:V28)
A29: 2 | B29: /showroom/vellfire/ | C29: 3515747 | D29: =C29/ $C$38 | E29: 2212061 | F29: =E29 / $E$38 | T29: Toyota Legender | U29: 264833 | V29: 44444 | W29: =SUM(U29:V29)
A30: 3 | B30: /showroom/glanza/ | C30: 3180166 | D30: =C30/ $C$38 | E30: 1926637 | F30: =E30 / $E$38 | K30: 42748 | L30: =K30/30 | T30: Toyota Glanza | U30: 3566533 | V30: 61226 | W30: =SUM(U30:V30)
A31: 4 | B31: /showroom/camry/ | C31: 2614892 | D31: =C31/ $C$38 | E31: 1319060 | F31: =E31 / $E$38 | T31: Toyota Hilux | U31: 541489 | V31: 43347 | W31: =SUM(U31:V31)
A32: 5 | B32: /showroom/urbancruiser-hyryder/ | C32: 2381580 | D32: =C32/ $C$38 | E32: 1116361 | F32: =E32 / $E$38 | T32: Toyota Innova Crysta | U32: 934355 | V32: 84613 | W32: =SUM(U32:V32)
A33: 6 | B33: /pricelist/ | C33: 1912540 | D33: =C33/ $C$38 | E33: 148244 | F33: =E33 / $E$38 | T33: Toyota Innova Hycross | U33: 1173201 | V33: 191154 | W33: =SUM(U33:V33)
A34: 7 | B34: /showroom/innova/ | C34: 1750094 | D34: =C34/ $C$38 | E34: 760295 | F34: =E34 / $E$38 | T34: Toyota Lc300 | U34: 284393 | V34: 33640 | W34: =SUM(U34:V34)
A35: 8 | B35: /showroom/urbancruiser-taisor/ | C35: 1193473 | D35: =C35/ $C$38 | E35: 390008 | F35: =E35 / $E$38 | T35: Toyota Rumion | U35: 466357 | V35: 42511 | W35: =SUM(U35:V35)
A36: 9 | B36: /showroom/fortuner/index-fortuner.html | C36: 1179052 | D36: =C36/ $C$38 | E36: 488040 | F36: =E36 / $E$38 | T36: Toyota Urbancruiser Hyryder | U36: 1752895 | V36: 140112 | W36: =SUM(U36:V36)
A37: 10 | B37: /showroom/innova-crysta/ | C37: 1139472 | D37: =C37/ $C$38 | E37: 521109 | F37: =E37 / $E$38 | T37: Toyota Urbancruiser Taisor | U37: 2468266 | V37: 578266 | W37: =SUM(U37:V37)
B38: Tottal | C38: 36882731 | D38: =SUM(D28:D37) | E38: 15081630 | F38: =SUM(F28:F37) | T38: Toyota Vellfire | U38: 282210 | V38: 37096 | W38: =SUM(U38:V38)
W39: =SUM(W27:W38)
A40: =" - Top 10 sections constitute " & TEXT(D38, "0.00%") & " of Page views. (Total Page views – " & TEXT(C38, "#,##0") & ")" & CHAR(10) & " - " & TEXT(F38, "0.00%") & " of page views are unique Page views for top 10 sections."

Sheet Traffic source
A1: Default Channel Grouping | B1: Sessions | C1: %
A2: Organic Search | B2: 806874 | C2: =B2/$B$19*100
A3: Paid Search | B3: 415912 | C3: =B3/$B$19*100
A4: Display | B4: 372255 | C4: =B4/$B$19*100
A5: Organic Social | B5: 192716 | C5: =B5/$B$19*100
A6: Paid Social | B6: 182035 | C6: =B6/$B$19*100
A7: Direct | B7: 177226 | C7: =B7/$B$19*100
A8: Unassigned | B8: 85196 | C8: =B8/$B$19*100
A9: Paid Shopping | B9: 30642 | C9: =B9/$B$19*100
A10: Referral | B10: 16787 | C10: =B10/$B$19*100
A11: Cross-network | B11: 14873 | C11: =B11/$B$19*100
A12: Paid Other | B12: 6449 | C12: =B12/$B$19*100
A13: Organic Shopping | B13: 6165 | C13: =B13/$B$19*100
... A17: Organic Shopping | B17: 1 | C17: =B17/$B$19*100
B19: 2306319
A23: Organic Search | B23: 565677 | C23: =B23/$B$19*100
A24: Paid Search | B24: 404592 | C24: =B24/$B$19*100
A25: Display | B25: 352160 | C25: =B25/$B$19*100
A26: Organic Social | B26: 187460 | C26: =B26/$B$19*100
A27: Paid Social | B27: 179858 | C27: =B27/$B$19*100
A28: Direct | B28: 156137 | C28: =B28/$B$19*100
A29: Unassigned | B29: 69391 | C29: =B29/$B$19*100
A30: Paid Shopping | B30: 30323 | C30: =B30/$B$19*100
A31: Cross-network | B31: 14588 | C31: =B31/$B$19*100
A32: Referral | B32: 10426 | C32: =B32/$B$19*100
A33: Organic Shopping | B33: 5945 | C33: =B33/$B$19*100
A34: Paid Other | B34: 5144 | C34: =B34/$B$19*100
... A38: Email | B38: 2 | C38: =B38/$B$19*100
B39: 1941298
A44: overall | G44: mobile
A46: SOURCES | B46: VISITS | C46: % VISITS | G46: SOURCES | H46: VISITS | I46: % VISITS
A47: google / organic | B47: 776423 | C47: =B47/$B$19 | G47: google / organic | H47: 564222 | I47: =H47/$B$39
A48: google / cpc | B48: 474628 | C48: =B48/$B$19 | G48: google / cpc | H48: 463124 | I48: =H48/$B$39
A49: (direct) / (none) | B49: 177226 | C49: =B49/$B$19 | G49: (direct) / (none) | H49: 156137 | I49: =H49/$B$39
A50: facebook / cpc | B50: 113513 | C50: =B50/$B$19 | G50: facebook / cpc | H50: 112878 | I50: =H50/$B$39
A51: linkedin / form | B51: 90985 | C51: =B51/$B$19 | G51: linkedin / form | H51: 88648 | I51: =H51/$B$39
A52: mygate / cpm | B52: 77794 | C52: =B52/$B$19 | G52: mygate / cpm | H52: 77411 | I52: =H52/$B$39
A53: facebook / cpl | B53: 66405 | C53: =B53/$B$19 | G53: facebook / cpl | H53: 65476 | I53: =H53/$B$39
A54: linkedin / form-p1 | B54: 64082 | C54: =B54/$B$19 | G54: linkedin / form-p1 | H54: 62596 | I54: =H54/$B$39
A55: spotify / cpm | B55: 39404 | C55: =B55/$B$19 | G55: spotify / cpm | H55: 38690 | I55: =H55/$B$39
...

Sheet age&gender
A1: userAgeBracket | B1: sessions | C1: %
A2: unknown | B2: 1709228 | C2: =SUM(B2/D2) | D2: ='Traffic source'!$B$19
A3: 25-34 | B3: 196054 | C3: =SUM(B3/D3) | D3: ='Traffic source'!$B$19
A4: 35-44 | B4: 141059 | C4: =SUM(B4/D4) | D4: ='Traffic source'!$B$19
A5: 18-24 | B5: 137720 | C5: =SUM(B5/D5) | D5: ='Traffic source'!$B$19
A6: 45-54 | B6: 68068 | C6: =SUM(B6/D6) | D6: ='Traffic source'!$B$19
A7: 55-64 | B7: 34165 | C7: =SUM(B7/D7) | D7: ='Traffic source'!$B$19
A8: 65+ | B8: 17110 | C8: =SUM(B8/D8) | D8: ='Traffic source'!$B$19
A9: (other) | B9: 58
A30: userGender | B30: sessions | C30: %
A31: unknown | B31: 1640292 | C31: =SUM(B31/D6)
A32: male | B32: 552487 | C32: =SUM(B32/D7)
A33: female | B33: 104914 | C33: =B33/D3
A34: (other) | B34: 58

Sheet browser
B1: Sessions | C1: % | D1: Users
A2: Chrome | B2: 1451672 | C2: =B2/$B$16 | D2: 971095
A3: Safari | B3: 334516 | C3: =B3/$B$16 | D3: 216514
A4: Android Webview | B4: 207751 | C4: =B4/$B$16 | D4: 199340
A5: Safari (in-app) | B5: 181696 | C5: =B5/$B$16 | D5: 172203
A6: Samsung Internet | B6: 76287 | C6: =B6/$B$16 | D6: 50071
A7: Edge | B7: 41207 | C7: =B7/$B$16 | D7: 22973
A8: Firefox | B8: 13813 | C8: =B8/$B$16 | D8: 9341
A9: Opera | B9: 9083 | C9: =B9/$B$16 | D9: 5910
A10: Internet Explorer | B10: 582 | C10: =B10/$B$16 | D10: 585
A11: UC Browser | B11: 483 | C11: =B11/$B$16 | D11: 430
A12: Mozilla Compatible Agent | B12: 464 | C12: =B12/$B$16 | D12: 452
A13: Android Browser | B13: 148 | D13: 148
A14: YaBrowser | B14: 96 | D14: 92
A15: Android Runtime | B15: 42 | D15: 35
A16: total = | B16: ='Traffic source'!B19

Sheet operatingSystem
B1: Sessions | C1: % | D1: Users
A2: Android | B2: 1417479 | C2: =B2/$B$16 | D2: 1030271
A3: iOS | B3: 575966 | C3: =B3/$B$16 | D3: 430533
A4: Windows | B4: 235391 | C4: =B4/$B$16 | D4: 138870
A5: Macintosh | B5: 65065 | C5: =B5/$B$16 | D5: 31241
A6: Linux | B6: 29540 | C6: =B6/$B$16 | D6: 18120
A7: Chrome OS | B7: 931 | C7: =B7/$B$16 | D7: 649
A8: Tizen | B8: 49 | C8: =B8/$B$16 | D8: 39
A9: Xbox | B9: 14 | C9: =B9/$B$16 | D9: 14
A10: Nokia | B10: 4 | C10: =B10/$B$16 | D10: 4
A11: Fuchsia | B11: 2 | C11: =B11/$B$16 | D11: 2
A12: Windows Phone | B12: 2 | C12: =B12/$B$16 | D12: 2
A13: SymbianOS | B13: 1 | D13: 1
A14: UNIX | B14: 2 | D14: 0
A15: BlackBerry | B15: 1 | D15: 1
A16: total = | B16: ='Traffic source'!B19

Sheet Landing&Exits
A1: PAGE | B1: VISITS | C1: PAGES / VISITS | D1: Views
A2: /showroom/camry | B2: 339804 | C2: 1.3051524 | D2: 443496
A3: /showroom/urbancruiser-hyryder | B3: 315407 | C3: 1.4191505 | D3: 447610
A4: / | B4: 304923 | C4: 3.3800107 | D4: 1030643
A5: /showroom/vellfire | B5: 219055 | C5: 1.2568533 | D5: 275320
A6: /campaign/urbancruiser-hyryder | B6: 193863 | C6: 1.226624 | D6: 237797
A7: /showroom/fortuner/index-fortuner.html | B7: 98202 | C7: 1.7906865 | D7: 175849 | E7: <=== OverAll
A8: /showroom/glanza | B8: 67267 | C8: 1.4307759 | D8: 96244
A9: /campaign/glanza/index.html | B9: 65507 | C9: 1.2797258 | D9: 83831
A10: /campaign/vellfire/index.html | B10: 64809 | C10: 1.1509204 | D10: 74590
A11: /campaign/lc300/index.html | B11: 64051 | C11: 1.0940344 | D11: 70074
A12: /showroom/innova | B12: 63762 | C12: 2.3007748 | D12: 146702
A13: (not set) | B13: 53505 | C13: 7.4759368e-05 | D13: 4
A14: /showroom/innova-crysta | B14: 50049 | C14: 1.8337429 | D14: 91777
A15: /pricelist | B15: 39414 | C15: 1.8800934 | D15: 74102
A16: /showroom/urbancruiser-taisor | B16: 30203 | C16: 2.2521935 | D16: 68023
A20: /showroom/vellfire | B20: 393139 | C20: 1.2029918 | D20: 472943
A21: /showroom/urbancruiser-hyryder | B21: 279009 | C21: 1.3783247 | D21: 384565
A22: /showroom/camry | B22: 275241 | C22: 1.2569821 | D22: 345973
A23: / | B23: 218232 | C23: 3.0941521 | D23: 675243 | E23: <=== mobile
A24: /showroom/vellfire | B24: 205935 | C24: 1.2573191 | D24: 258926
A25: /campaign/urbancruiser-hyryder | B25: 189121 | C25: 1.2160469 | D25: 229980
A26: /showroom/fortuner/index-fortuner.html | B26: 87553 | C26: 1.6849223 | D26: 147520
A27: /campaign/glanza/index.html | B27: 64747 | C27: 1.2722752 | D27: 82376
A28: /campaign/lc300/index.html | B28: 63800 | C28: 1.0896395 | D28: 69519
A29: /campaign/vellfire/index.html | B29: 63349 | C29: 1.1386447 | D29: 72132
A30: /showroom/glanza | B30: 58060 | C30: 1.3537031 | D30: 78596
A31: /showroom/innova | B31: 46107 | C31: 2.0041425 | D31: 92405
A32: /showroom/innova-crysta | B32: 39789 | C32: 1.7398025 | D32: 69225
A33: /pricelist | B33: 33862 | C33: 1.7981218 | D33: 60888
A34: (not set) | B34: 22950 | C34: 8.7145969e-05 | D34: 2
A35: /campaign/hilux | B35: 22528 | C35: 1.5021751 | D35: 33841

Sheet kpimonthly
A1: Sl. No. | B1: Pages | C1: Avg. Load Time | D1: Bounce Rate | E1: Time Spent | F1: Total Pageviews | G1: Per day Avg | H1: Total Unique Pageviews | I1: Per day Avg.
A2: 1 | B2: Overall Website (Avg) | C2: 6.15 | D2: 0.5507 | E2: 0.0016319444 | F2: ='Site - Month Graph'!D35 | G2: =F2/330 | H2: 1772011 | I2: =H2/31
A3: 2 | B3: Home Page | C3: 6.2 | D3: 0.15210227 | E3: 00:01:20 | F3: 430102 | G3: 14336.733 | H3: 260116 | I3: 8670.5333
A4: 3 | B4: Product Pages (Avg) | C4: 6.45 | D4: =AVERAGE(D5:D16) | E4: =AVERAGE(E5:E16) | F4: =AVERAGE(F5:F16) | G4: =AVERAGE(G5:G16) | H4: =AVERAGE(H5:H16) | I4: =AVERAGE(I5:I16)
A5: 3.1 | B5: Camry | C5: 5.4 | D5: 0.70074484 | E5: 0.00069444444 | F5: 374831 | G5: 12494.367 | H5: 235224 | I5: 7840.8
A6: 3.2 | B6: Fortuner | C6: 5.9 | D6: 0.1958263 | E6: 0.0013657407 | F6: 94945 | G6: 3164.8333 | H6: 63548 | I6: 2118.2667
A7: 3.3 | B7: Legender | C7: 5.3 | D7: 0.15771682 | E7: 0.0010069444 | F7: 42017 | G7: 1400.5667 | H7: 30606 | I7: 1020.2
A8: 3.4 | B8: Glanza | C8: 4.5 | D8: 0.329162 | E8: 0.0012037037 | F8: 101674 | G8: 3389.1333 | H8: 72737 | I8: 2424.5667
A9: 3.5 | B9: Hilux | C9: 8.6 | D9: 0.20330687 | E9: 0.0013425926 | F9: 49313 | G9: 1643.7667 | H9: 35118 | I9: 1170.6
A10: 3.6 | B10: Innova Crysta | C10: 7 | D10: 0.30230265 | E10: 0.0011689815 | F10: 130570 | G10: 4352.3333 | H10: 93098 | I10: 3103.2667
A11: 3.7 | B11: Innova Hycross | C11: 7.7 | D11: 0.14842466 | E11: 0.0019444444 | F11: 138000 | G11: 4600 | H11: 91598 | I11: 3053.2667
A12: 3.8 | B12: LC300 | C12: 5 | D12: 0.27607529 | E12: 0.0010532407 | F12: 55440 | G12: 1848 | H12: 40994 | I12: 1366.4667
A13: 3.9 | B13: Rumion | C13: 7.3 | D13: 0.11782898 | E13: 0.0019907407 | F13: 37604 | G13: 1253.4667 | H13: 27559 | I13: 918.63333
A14: 3.1 | B14: UC Hyryder | C14: 5.7 | D14: 0.37973878 | E14: 0.0012615741 | F14: 271593 | G14: 9053.1 | H14: 189160 | I14: 6305.3333
A15: 3.11 | B15: UC Taisor | C15: 8.6 | D15: 0.1469796 | E15: 0.0016087963 | F15: 107646 | G15: 3588.2 | H15: 65869 | I15: 2195.6333
A16: 3.12 | B16: Vellfire | C16: 6.5 | D16: 0.68866257 | E16: 0.00081018519 | F16: 479106 | G16: 15970.2 | H16: 336304 | I16: 11210.133
A17: 4 | B17: Mobility Solution | C17: 2.4 | D17: 0.0674 | E17: 0.00070601852 | F17: 7,380 | G17: 246 | H17: 5,674 | I17: 189
A30: Sl. No. | B30: Pages | C30: Bounce Rate | D30: Time Spent | E30: Total Pageviews | F30: Per day Avg | G30: Total Unique Pageviews | H30: Per day Avg.
A31: 1 | B31: Overall Website (Avg) | C31: 0.5276 | D31: 0.0016666667 | E31: 32929122 | F31: =E31/244 | G31: 13785194 | H31: =G31/244
A32: 2 | B32: Home Page | C32: 0.22210416 | D32: 00:01:12 | E32: 3923270 | F32: 14370.952 | G32: 2207966 | H32: 8087.7875 | I32: /
A33: 3 | B33: Product Pages (Avg) | C33: =AVERAGE(C34:C45) | D33: =AVERAGE(D34:D45) | E33: =AVERAGE(E34:E45) | F33: =AVERAGE(F34:F45) | G33: =AVERAGE(G34:G45) | H33: =AVERAGE(H34:H45)
A34: 3.1 | B34: Camry | C34: 0.6056433 | D34: 0.00075231481 | E34: 2179236 | F34: 7982.5495 | G34: 1226655 | H34: 4493.2418 | I34: /showroom/camry/
A35: 3.2 | B35: Fortuner | C35: 0.33169321 | D35: 0.001099537 | E35: 1009686 | F35: 3698.4835 | G35: 681480 | H35: 2496.2637 | I35: /showroom/fortuner/index-fortuner.html
A36: 3.3 | B36: Legender | C36: 0.53213985 | D36: 0.00068287037 | E36: 783420 | F36: 2869.6703 | G36: 529168 | H36: 1938.3443 | I36: /showroom/fortuner/index-legender.html
A37: 3.4 | B37: Glanza | C37: 0.60927815 | D37: 0.00099537037 | E37: 3064049 | F37: 11223.623 | G37: 2071028 | H37: 7586.1832 | I37: /showroom/glanza/
A38: 3.5 | B38: Hilux | C38: 0.44216353 | D38: 0.00092592593 | E38: 941260 | F38: 3447.8388 | G38: 714782 | H38: 2618.2491 | I38: /showroom/hilux/
A39: 3.6 | B39: Innova Crysta | C39: 0.37920449 | D39: 0.001087963 | E39: 1035137 | F39: 3791.7106 | G39: 751981 | H39: 2754.5092 | I39: /showroom/innova-crysta/
A40: 3.7 | B40: Innova Hycross | C40: 0.26967002 | D40: 0.002025463 | E40: 1614531 | F40: 5914.033 | G40: 1073989 | H40: 3934.0256 | I40: /showroom/innova/
A41: 3.8 | B41: LC300 | C41: 0.2002162 | D41: 0.0012152778 | E41: 400594 | F41: 1467.3773 | G41: 291576 | H41: 1068.044 | I41: /showroom/lc300/
A42: 3.9 | B42: Rumion | C42: 0.12385356 | D42: 0.0020949074 | E42: 318360 | F42: 1166.1538 | G42: 217209 | H42: 795.63736 | I42: /showroom/rumion/
A43: 3.1 | B43: UC Hyryder | C43: 0.34725202 | D43: 0.001412037 | E43: 1947223 | F43: 7132.685 | G43: 1238525 | H43: 4536.7216 | I43: /showroom/urbancruiser-hyryder/
A44: 3.11 | B44: UC Taisor | C44: 0.34921535 | D44: 0.0012152778 | E44: 1089517 | F44: 3990.9048 | G44: 697770 | H44: 2555.9341 | I44: /showroom/urbancruiser-taisor/
A45: 3.12 | B45: Vellfire | C45: 0.64596175 | D45: 0.00083333333 | E45: 3242654 | F45: 11877.853 | G45: 2224581 | H45: 8148.6484 | I45: /showroom/vellfire/
A46: 4 | B46: Mobility Solution | C46: 0.05489425 | D46: 0.00075231481 | E46: 68919 | F46: 252.45055 | G46: 50750 | H46: 185.89744 | I46: /mobility-solutions/

Sheet tfsinKpi
A1: No. of Monthly Visitors (Toyotabharat website) | B1: ='No of Visitors'!B7
A2: Online Enquiries/Leads(organic leads) | B2: ='tbltransaction-organic'!N8
A3: No. of Visitors for TFS Landing Page | B3: 1944
A4: No. of Visitors for EMI Calculator | B4: 6315
A5: No. of Apply for Loan Clicks | B5: 1782
A6: No. of Clicks on TFS Logo placed on Page Footer | B6: 423

Sheet referringSites
A1: SOURCE | B1: VISITS | C1: PAGES/VISIT | D1: Views
A2: toyotapartsconnect.in / referral | B2: 1290 | C2: =D2/B2 | D2: 2934
A3: toyotafinance.co.in / referral | B3: 1167 | C3: =D3/B3 | D3: 2745
A4: surveys.numr.app / referral | B4: 857 | C4: =D4/B4 | D4: 1126
A5: chatgpt.com / referral | B5: 761 | C5: =D5/B5 | D5: 1643
A6: bharattoyota.com / referral | B6: 582 | C6: =D6/B6 | D6: 2982
A7: nippon-toyota.com / referral | B7: 568 | C7: =D7/B7 | D7: 1251
A8: jobsaddafreshers.com / referral | B8: 506 | C8: =D8/B8 | D8: 781
A9: drum-tao.com / referral | B9: 489 | C9: =D9/B9 | D9: 736
A10: l.wl.co / referral | B10: 431 | C10: =D10/B10 | D10: 939
A11: millennium-toyota.com / referral | B11: 331 | C11: =D11/B11 | D11: 878
A12: harshatoyota.com / referral | B12: 315 | C12: =D12/B12 | D12: 790
A13: nanditoyota.com / referral | B13: 306 | C13: =D13/B13 | D13: 685
... A16: anaamalaistoyota.com / referral | B16: 258 | C16: =D16/B16 | D16: 512
B4387: =SUM(B2:B4386) | D4387: =SUM(D2:D4386) | E4387: =D4387/B4387

Sheet MoM-Growth
A1: month 2(current) | B1: month 1(last) | C1: (Month 2 - Month 1) / Month 1 * 100
A2: 1815975 | B2: 1452406 | C2: =SUM(A2-B2)/B2*100 | F2: 1452406
A3: 148616 | B3: 127069 | C3: =SUM(A3-B3)/B3*100 | F3: 127069
A4: 1649903 | B4: 1281828 | C4: =SUM(A4-B4)/B4*100 | F4: 1281828
A5: 1.74 | B5: 1.71 | C5: =SUM(A5-B5)/B5*100 | F5: 1.71
A6: 0.0016319444 | B6: 0.0017361111 | C6: =SUM(A6-B6)/B6*100 | F6: 0.0017361111
A7: 2306319 | B7: 1883860 | C7: =SUM(A7-B7)/B7*100 | F7: 1883860
A8: 4009027 | B8: 3322431 | C8: =SUM(A8-B8)/B8*100 | F8: 3322431
A9: 6252 | B9: 5807 | C9: =SUM(A9-B9)/B9*100 | F9: 5807
A10: 34 | B10: 36 | C10: =SUM(A10-B10)/B10*100 | F10: 36

Sheet daywiseOneMonthVisits
D1: 01 | F1: 02 | H1: 03 | J1: 04 | L1: 05 | N1: 06 | P1: 07 | R1: 08
C2: Users | D2: 1282252 | F2: 907472 | H2: 1023639 | J2: 838837 | L2: 1111927 | N2: 2761059 | P2: 3349424 | R2: 796861
C3: Visits (Sessions) | D3: 1750181 | F3: 1300740 | H3: 1298056 | J3: 1123222 | L3: 1386083 | N3: 3436416 | P3: 4167538 | R3: 1013091
C4: Average Time on Site | D4: 141.91061 | F4: 160.32509968953289 | H4: 167.84903 | J4: 194.26855 | L4: 192.99797452930019 | N4: 123.9368 | P4: 117.77713 | R4: 173.41305
C5: Unique Users | D5: 1190484 | F5: 786757 | H5: 942198 | J5: 763581 | L5: 1033522 | N5: 2627860 | P5: 3131840 | R5: 675742
C6: Page Views | D6: 3144863 | F6: 2467315 | H6: 2458860 | J6: 2268137 | L6: 2863687 | N6: 5582723 | P6: 6812079 | R6: 1857074
D8: 01 | F8: 02 | H8: 03 | J8: 04 | L8: 05 | N8: 06 | P8: 07 | R8: 08
C9: Users | D9: 752812 | F9: 1952754 | H9: 1088842 | J9: 1822296 | L9: 1853288 | N9: 1647389 | P9: 1931770 | R9: 1196522
C10: Visits (Sessions) | D10: 975150 | F10: 2626352 | H10: 1505441 | J10: 2274026 | L10: 2295053 | N10: 2072987 | P10: 2318344 | R10: 1685981
C11: Average Time on Site | D11: 203.00204 | F11: 144.00022 | H11: 146.44372248043729 | J11: 138.74365894955909 | L11: 131.81292 | N11: 127.72968 | P11: 122.84738 | R11: 150.96375
C12: Unique Users | D12: 686734 | F12: 1860236 | H12: 1019478 | J12: 1696705 | L12: 1743838 | N12: 1538599 | P12: 1786408 | R12: 1131167
C13: Page Views | D13: 1954636 | F13: 4344916 | H13: 2538338 | J13: 3850224 | L13: 3699781 | N13: 3314614 | P13: 3748100 | R13: 2932771
C14: page/visti | D14: =D13/D10 | F14: =F13/F10 | H14: =H13/H10 | J14: =J13/J10 | L14: =L13/L10 | N14: =N13/N10 | P14: =P13/P10 | R14: =R13/R10
D15: 2.0044465 | F15: 1.654354 | H15: 1.6861093 | J15: 1.693131 | L15: 1.6120678 | N15: 1.5989555 | P15: 1.6167143 | R15: 1.7395042
B73: 03
B74: 25
B75: 29
B76: 5.2740250689655177
B77: 0
B78: 0
B82: 02
B83: 2
B84: 2
B85: 5.029166
B86: 0
B87: 0
B91: 01
B92: 1
B93: 1
B94: 5.042405
B95: 0
B96: 0
B100: 03
B101: 1
B102: 1
B103: 4.760844
B104: 0
B105: 0
B109: 01
B110: 1
...

Sheet sesionIntrest
A1: BRANDINGINTEREST | B1: SESSIONS
A2: Banking & Finance/Avid Investors | B2: 107763
A3: Technology/Technophiles | B3: 89139
A4: News & Politics/Avid News Readers/Entertainment News Enthusiasts | B4: 87759
A5: Sports & Fitness/Sports Fans/Cricket Enthusiasts | B5: 85119
A6: Media & Entertainment/Movie Lovers/Fans of South Asian Film | B6: 83474
A7: Travel/Travel Buffs | B7: 81083
A8: News & Politics/Avid News Readers | B8: 78930
A9: News & Politics/Avid News Readers/Avid Business News Readers | B9: 78537
A10: Vehicles & Transportation/Auto Enthusiasts | B10: 72882
A11: Technology/Mobile Enthusiasts | B11: 70978
A12: Lifestyles & Hobbies/Shutterbugs | B12: 51982
A13: News & Politics/Avid News Readers/Avid Political News Readers | B13: 49232
... A16: Sports & Fitness/Sports Fans | B16: 35155
B22: =

Sheet networkReferral
A1: SOCIAL NETWORK | B1: VISITS | C1: PAGE VIEWS | D1: PAGES / VISITS
A2: facebook | B2: 1175 | C2: 1584 | D2: 1.3480851
A3: instagram | B3: 504 | C3: 1565 | D3: 3.1051587
A4: t.co / referral | B4: 229 | C4: 396 | D4: 1.7292576
A5: bit.ly / referral | B5: 43 | C5: 49 | D5: 1.1395349
A6: linkedin | B6: 26 | C6: 44 | D6: 1.6923077
A7: tripadvisor.com / referral | B7: 2 | C7: 3 | D7: 1.5
A8: pinterest | B8: 2 | C8: 2 | D8: 1
A9: snapchat.com / referral | B9: 1 | C9: 1 | D9: 1
A10: yourcarwala.blogspot.com / referral | B10: 1 | C10: 1 | D10: 1
A11: tripadvisor.com.my / referral | B11: 1 | C11: 1 | D11: 1

Sheet kpi-montly&year
A1: https://analytics.google.com/analytics/web/?utm_source=marketingplatform.google.com&utm_medium=et&utm_campaign=marketingplatform.google.com%2Fabout%2Fanalytics%2F#/p353077807/reports/explorer?params=_u..nav%3Dmaui%26_u.comparisonOption%3Ddisabled%26_u.date00%3D20240901%26_u.date01%3D20240930%26_r..dataFilters%3D%5B%7B%22type%22:1,%22fieldName%22:%22unifiedPagePathScreen%22,%22evaluationType%22:8,%22expressionList%22:%5B%22%252Fshowroom%252Finnova%252F%22,%22%252F%22,%22%252Fshowroom%252Furbancruiser-hyryder%252F%22,%22%252Fshowroom%252Frumion%252F%22,%22%252Fshowroom%252Furbancruiser-taisor%252F%22,%22%252Fshowroom%252Ffortuner%252Findex-fortuner.html%22,%22%252Fshowroom%252Finnova-crysta%252F%22,%22%252Fshowroom%252Fglanza%252F%22,%22%252Fshowroom%252Fhilux%252F%22,%22%252Fshowroom%252Ffortuner%252Findex-legender.html%22,%22%252Fshowroom%252Fcamry%252F%22,%22%252Fshowroom%252Fvellfire%252F%22,%22%252Fshowroom%252Flc300%252F%22,%22%252Ftoyota-in-india%252Fdelivery-lead-time%252F%22,%22%252Fmobility-solutions%252F%22%5D,%22complement%22:false,%22isCaseSensitive%22:true,%22expression%22:%22%22%7D%5D%26_r.explorerCard..startRow%3D0%26_r.explorerCard..rowsPerPage%3D25&r=6510807527&ruid=all-pages-and-screens,life-cycle,engagement&collectionId=6342606963
A4: Sl. No. | B4: Pages | C4: Avg. Load Time | D4: Bounce Rate | E4: Time Spent | F4: Total Pageviews | G4: Per day Avg | H4: Total Unique Pageviews | I4: Per day Avg.
A5: 1 | B5: Overall Website (Avg) | C5: 6.8 | D5: 0.5619 | E5: 0.0014236111 | F5: 5582723 | G5: =Table1879101112131415161718192021222324252627282930313233343536373839404142434448495152535455565758596263646568697071[[#This Row],[Total Pageviews]]/30 | H5: 2721899 | I5: =Table1879101112131415161718192021222324252627282930313233343536373839404142434448495152535455565758596263646568697071[[#This Row],[Total Unique Pageviews]]/30
A6: 2 | B6: Home Page | C6: 4.8 | D6: =TEXT(B25*100, "0.00") & "%" | E6: =TEXT(INT(C25/3600), "00") & ":" & TEXT(INT(MOD(C25, 3600)/60), "00") & ":" & TEXT(MOD(C25, 60), "00") | F6: 448494 | G6: =Table1879101112131415161718192021222324252627282930313233343536373839404142434448495152535455565758596263646568697071[[#This Row],[Total Pageviews]]/30 | H6: 247711 | I6: =Table1879101112131415161718192021222324252627282930313233343536373839404142434448495152535455565758596263646568697071[[#This Row],[Total Unique Pageviews]]/30
A7: 3 | B7: Product Pages (Avg) | C7: 7.6 | D7: 0.3368 | E7: =TEXT(INT(C40/3600), "00") & ":" & TEXT(INT(MOD(C40, 3600)/60), "00") & ":" & TEXT(MOD(C40, 60), "00") | F7: =AVERAGE(F8:F19) | G7: =Table1879101112131415161718192021222324252627282930313233343536373839404142434448495152535455565758596263646568697071[[#This Row],[Total Pageviews]]/30 | H7: =AVERAGE(H8:H19) | I7: =Table1879101112131415161718192021222324252627282930313233343536373839404142434448495152535455565758596263646568697071[[#This Row],[Total Unique Pageviews]]/30
A8: 3.1 | B8: Camry | C8: 9 | D8: =TEXT(B26*100, "0.00") & "%" | E8: =TEXT(INT(C26/3600), "00") & ":" & TEXT(INT(MOD(C26, 3600)/60), "00") & ":" & TEXT(MOD(C26, 60), "00") | F8: 38649 | G8: =Table1879101112131415161718192021222324252627282930313233343536373839404142434448495152535455565758596263646568697071[[#This Row],[Total Pageviews]]/30 | H8: 28688 | I8: =Table1879101112131415161718192021222324252627282930313233343536373839404142434448495152535455565758596263646568697071[[#This Row],[Total Unique Pageviews]]/30
A9: 3.2 | B9: Fortuner | C9: 8.9 | D9: =TEXT(B27*100, "0.00") & "%" | E9: =TEXT(INT(C27/3600), "00") & ":" & TEXT(INT(MOD(C27, 3600)/60), "00") & ":" & TEXT(MOD(C27, 60), "00") | F9: 231412 | G9: =Table1879101112131415161718192021222324252627282930313233343536373839404142434448495152535455565758596263646568697071[[#This Row],[Total Pageviews]]/30 | H9: 174732 | I9: =Table1879101112131415161718192021222324252627282930313233343536373839404142434448495152535455565758596263646568697071[[#This Row],[Total Unique Pageviews]]/30
A10: 3.3 | B10: Legender | C10: 6.8 | D10: =TEXT(B28*100, "0.00") & "%" | E10: =TEXT(INT(C28/3600), "00") & ":" & TEXT(INT(MOD(C28, 3600)/60), "00") & ":" & TEXT(MOD(C28, 60), "00") | F10: 45031 | G10: =Table1879101112131415161718192021222324252627282930313233343536373839404142434448495152535455565758596263646568697071[[#This Row],[Total Pageviews]]/30 | H10: 32702 | I10: =Table1879101112131415161718192021222324252627282930313233343536373839404142434448495152535455565758596263646568697071[[#This Row],[Total Unique Pageviews]]/30
A11: 3.4 | B11: Glanza | C11: 9.2 | D11: =TEXT(B29*100, "0.00") & "%" | E11: =TEXT(INT(C29/3600), "00") & ":" & TEXT(INT(MOD(C29, 3600)/60), "00") & ":" & TEXT(MOD(C29, 60), "00") | F11: 563690 | G11: =Table1879101112131415161718192021222324252627282930313233343536373839404142434448495152535455565758596263646568697071[[#This Row],[Total Pageviews]]/30 | H11: 432835 | I11: =Table1879101112131415161718192021222324252627282930313233343536373839404142434448495152535455565758596263646568697071[[#This Row],[Total Unique Pageviews]]/30
A12: 3.5 | B12: Hilux | C12: 7.7 | D12: =TEXT(B30*100, "0.00") & "%" | E12: =TEXT(INT(C30/3600), "00") & ":" & TEXT(INT(MOD(C30, 3600)/60), "00") & ":" & TEXT(MOD(C30, 60), "00") | F12: 183825 | G12: =Table1879101112131415161718192021222324252627282930313233343536373839404142434448495152535455565758596263646568697071[[#This Row],[Total Pageviews]]/30 | H12: 155711 | I12: =Table1879101112131415161718192021222324252627282930313233343536373839404142434448495152535455565758596263646568697071[[#This Row],[Total Unique Pageviews]]/30
A13: 3.6 | B13: Innova Hycross | C13: 8.3 | D13: =TEXT(B31*100, "0.00") & "%" | E13: =TEXT(INT(C31/3600), "00") & ":" & TEXT(INT(MOD(C31, 3600)/60), "00") & ":" & TEXT(MOD(C31, 60), "00") | F13: 264319 | G13: =Table1879101112131415161718192021222324252627282930313233343536373839404142434448495152535455565758596263646568697071[[#This Row],[Total Pageviews]]/30 | H13: 182457 | I13: =Table1879101112131415161718192021222324252627282930313233343536373839404142434448495152535455565758596263646568697071[[#This Row],[Total Unique Pageviews]]/30
A14: 3.7 | B14: Innova Crysta | C14: 7.8 | D14: =TEXT(B32*100, "0.00") & "%" | E14: =TEXT(INT(C32/3600), "00") & ":" & TEXT(INT(MOD(C32, 3600)/60), "00") & ":" & TEXT(MOD(C32, 60), "00") | F14: 290309 | G14: =Table1879101112131415161718192021222324252627282930313233343536373839404142434448495152535455565758596263646568697071[[#This Row],[Total Pageviews]]/30 | H14: 242887 | I14: =Table1879101112131415161718192021222324252627282930313233343536373839404142434448495152535455565758596263646568697071[[#This Row],[Total Unique Pageviews]]/30
A15: 3.8 | B15: LC300 | C15: 6 | D15: =TEXT(B33*100, "0.00") & "%" | E15: =TEXT(INT(C33/3600), "00") & ":" & TEXT(INT(MOD(C33, 3600)/60), "00") & ":" & TEXT(MOD(C33, 60), "00") | F15: 36637 | G15: =Table1879101112131415161718192021222324252627282930313233343536373839404142434448495152535455565758596263646568697071[[#This Row],[Total Pageviews]]/30 | H15: 27307 | I15: =Table1879101112131415161718192021222324252627282930313233343536373839404142434448495152535455565758596263646568697071[[#This Row],[Total Unique Pageviews]]/30
A16: 3.9 | B16: Rumion | C16: 5.6 | D16: =TEXT(B34*100, "0.00") & "%" | E16: =TEXT(INT(C34/3600), "00") & ":" & TEXT(INT(MOD(C34, 3600)/60), "00") & ":" & TEXT(MOD(C34, 60), "00") | F16: 36542 | G16: =Table1879101112131415161718192021222324252627282930313233343536373839404142434448495152535455565758596263646568697071[[#This Row],[Total Pageviews]]/30 | H16: 26669 | I16: =Table1879101112131415161718192021222324252627282930313233343536373839404142434448495152535455565758596263646568697071[[#This Row],[Total Unique Pageviews]]/30
A17: 3.1 | B17: UC Hyryder | C17: 6.7 | D17: =TEXT(B35*100, "0.00") & "%" | E17: =TEXT(INT(C35/3600), "00") & ":" & TEXT(INT(MOD(C35, 3600)/60), "00") & ":" & TEXT(MOD(C35, 60), "00") | F17: 352173 | G17: =Table1879101112131415161718192021222324252627282930313233343536373839404142434448495152535455565758596263646568697071[[#This Row],[Total Pageviews]]/30 | H17: 244231 | I17: =Table1879101112131415161718192021222324252627282930313233343536373839404142434448495152535455565758596263646568697071[[#This Row],[Total Unique Pageviews]]/30
A18: 3.11 | B18: UC Taisor | C18: 7.3 | D18: =TEXT(B36*100, "0.00") & "%" | E18: =TEXT(INT(C36/3600), "00") & ":" & TEXT(INT(MOD(C36, 3600)/60), "00") & ":" & TEXT(MOD(C36, 60), "00") | F18: 92195 | G18: =Table1879101112131415161718192021222324252627282930313233343536373839404142434448495152535455565758596263646568697071[[#This Row],[Total Pageviews]]/30 | H18: 57189 | I18: =Table1879101112131415161718192021222324252627282930313233343536373839404142434448495152535455565758596263646568697071[[#This Row],[Total Unique Pageviews]]/30
A19: 3.12 | B19: Vellfire | C19: 8.7 | D19: =TEXT(B37*100, "0.00") & "%" | E19: =TEXT(INT(C37/3600), "00") & ":" & TEXT(INT(MOD(C37, 3600)/60), "00") & ":" & TEXT(MOD(C37, 60), "00") | F19: 1228913 | G19: =Table1879101112131415161718192021222324252627282930313233343536373839404142434448495152535455565758596263646568697071[[#This Row],[Total Pageviews]]/30 | H19: 845472 | I19: =Table1879101112131415161718192021222324252627282930313233343536373839404142434448495152535455565758596263646568697071[[#This Row],[Total Unique Pageviews]]/30
... A21: 5 | B21: Delivery Lead Time | C21: 2.9 | D21: =TEXT(B39*100, "0.00") & "%" | E21: =TEXT(INT(C39/3600), "00") & ":" & TEXT(INT(MOD(C39, 3600)/60), "00") & ":" & TEXT(MOD(C39, 60), "00") | F21: 12025 | G21: =Table1879101112131415161718192021222324252627282930313233343536373839404142434448495152535455565758596263646568697071[[#This Row],[Total Pageviews]]/30 | H21: 9056 | I21: =Table1879101112131415161718192021222324252627282930313233343536373839404142434448495152535455565758596263646568697071[[#This Row],[Total Unique Pageviews]]/30
A24: Page path and screen class | B24: Bounce rate | C24: Average session duration | D24: Views | E24: Active users | G24: avg of product
B25: 0.1550508 | C25: 75.582028 | D25: 448494
A26: camry/ | B26: 0.11958905 | C26: 104.29218 | D26: 38649 | E26: 24018 | G26: 19.41 | H26: 11.96
A27: fortuner.html | B27: 0.48448263 | C27: 73.198863 | D27: 231412 | E27: 54859 | G27: 21.93 | H27: 48.45
A28: fortuner/index-legender.html | B28: 0.099095384 | C28: 96.07158 | D28: 45031 | E28: 23370 | G28: 16.51 | H28: 9.91
A29: glanza/ | B29: 0.64034771 | C29: 72.757911 | D29: 563690 | E29: 39291 | G29: 23.31 | H29: 64.03
A30: hilux/ | B30: 0.37586373 | C30: 84.653908 | D30: 183825 | E30: 35447 | G30: 26.83 | H30: 37.59
A31: innova/ | B31: 0.26869274 | C31: 186.51806 | D31: 264319 | E31: 146848 | G31: 42.73 | H31: 26.87
A32: innova-crysta/ | B32: 0.66024563 | C32: 59.15243 | D32: 290309 | E32: 55622 | G32: 21.65 | H32: 66.02
A33: lc300/ | B33: 0.11559586 | C33: 105.92176 | D33: 36637 | E33: 22626 | G33: 13.79 | H33: 11.56
A34: rumion/ | B34: 0.11607115 | C34: 194.55944 | D34: 36542 | E34: 28347 | G34: 12.97 | H34: 11.61
A35: urbancruiser-hyryder/ | B35: 0.37532915 | C35: 109.48365 | D35: 352173 | E35: 87350 | G35: 26.13 | H35: 37.53
A36: urbancruiser-taisor/ | B36: 0.14585016 | C36: 135.53566 | D36: 92195 | E36: 79384 | G36: 18.24 | H36: 14.59
A37: vellfire/ | B37: 0.64129149 | C37: 81.861924 | D37: 1228913 | E37: 22132 | G37: 21.01 | H37: 64.13
A38: mobility-solutions/ | B38: 0.05897772 | C38: 60.43541 | D38: 8211 | E38: 4582
A39: toyota-in-india/delivery-lead-time/ | B39: 0.20010355 | C39: 115.48268 | D39: 12025 | E39: 9056
C40: =AVERAGE(C26:C37)
A45: Sl. No. | B45: Pages | C45: Bounce Rate | D45: Time Spent | E45: Total Pageviews | F45: Per day Avg | G45: Total Unique Pageviews | H45: Per day Avg.
A46: 1 | B46: Overall Website (Avg) | C46: 0.5452 | D46: 0.0016435185 | E46: 18785585 | F46: =Table18791011121314151617181920212223242526272829303132333435363738394041424344484951525354555657585962636465686970713[[#This Row],[Total Pageviews]]/181 | G46: 7522783 | H46: =Table18791011121314151617181920212223242526272829303132333435363738394041424344484951525354555657585962636465686970713[[#This Row],[Total Unique Pageviews]]/181
A47: 2 | B47: Home Page | C47: =TEXT(B69*100, "0.00") & "%" | D47: =TEXT(INT(C69/3600), "00") & ":" & TEXT(INT(MOD(C69, 3600)/60), "00") & ":" & TEXT(MOD(C69, 60), "00") | E47: 2535514 | F47: =Table18791011121314151617181920212223242526272829303132333435363738394041424344484951525354555657585962636465686970713[[#This Row],[Total Pageviews]]/181 | G47: 1482436 | H47: =Table18791011121314151617181920212223242526272829303132333435363738394041424344484951525354555657585962636465686970713[[#This Row],[Total Unique Pageviews]]/181
A48: 3 | B48: Product Pages (Avg) | C48: 0.343 | D48: =TEXT(INT(C85/3600), "00") & ":" & TEXT(INT(MOD(C85, 3600)/60), "00") & ":" & TEXT(MOD(C85, 60), "00") | E48: =AVERAGE(E49:E60) | F48: =Table18791011121314151617181920212223242526272829303132333435363738394041424344484951525354555657585962636465686970713[[#This Row],[Total Pageviews]]/181 | G48: =AVERAGE(G49:G60) | H48: =Table18791011121314151617181920212223242526272829303132333435363738394041424344484951525354555657585962636465686970713[[#This Row],[Total Unique Pageviews]]/181
A49: 3.1 | B49: Camry | C49: =TEXT(B70*100, "0.00") & "%" | D49: =TEXT(INT(C70/3600), "00") & ":" & TEXT(INT(MOD(C70, 3600)/60), "00") & ":" & TEXT(MOD(C70, 60), "00") | E49: 1650045 | F49: =Table18791011121314151617181920212223242526272829303132333435363738394041424344484951525354555657585962636465686970713[[#This Row],[Total Pageviews]]/181 | G49: 883450 | H49: =Table18791011121314151617181920212223242526272829303132333435363738394041424344484951525354555657585962636465686970713[[#This Row],[Total Unique Pageviews]]/181
...

Sheet Dealer-Website
A1: Dealership | B1: Visits
A2: Ravindu Toyota | B2: 19843
A3: Millennium Toyota | B3: 15560
A4: Uttam Toyota | B4: 15256
A5: Nippon Toyota | B5: 14535
A6: Amana Toyota | B6: 9640 | T6: Lanson Toyota | U6: 4902
A7: Nandi Toyota | B7: 8309
A8: Harsha Toyota | B8: 7741 | T8: DSK Toyota | U8: 4751
A9: Lanson Toyota | B9: 7534 | T9: Galaxy Toyota | U9: 4213
A10: Anaamalais Toyota Trichy | B10: 7417
A11: Viva Toyota | B11: 6283 | T11: Infinium Toyota | U11: 2108
A12: Budha Toyota | B12: 4750 | T12: Millennium Toyota | U12: 1785
A13: Topsel Toyota | B13: 4289 | T13: Mgf Toyota | U13: 1476
A14: Globe Toyota | B14: 4256 | T14: Pioneer Toyota | U14: 1570
A15: J D Toyota | B15: 4178 | T15: Lakozy Toyota | U15: 1847
A16: Saini Toyota | B16: 3602
A17: Kairali Toyota | B17: 3498
A18: Anaamalais Toyota | B18: 3015
A19: Shodha Toyota | D19: 1144
A20: Uttam Toyota
A21: Madhuban Toyota
A22: Sharayu Toyota
A23: Topsel Toyota
A24: Shaw Toyota
A25: Rajendra Toyota
A26: Rajendra Toyota
A27: Sonak Toyota
A28: Anaamalais Toyota
A29: Anaamalais Toyota
A30: Wasan Toyota
A31: Saini Toyota
... A35: Om Toyota
A36: Mody Toyota | E36: March
A37: Rajyog Toyota | E37: before sorting | F37: b | H37: name | I37: views
A38: J D Toyota | E38: Nippon Toyota | F38: 5645645 | H38: Nippon Toyota | I38: 6546516
A39: Commercial Toyota | E39: Nandi Toyota | F39: 4488 | H39: Nandi Toyota | I39: 4286
A40: IJM Toyota | E40: Lanson Toyota | F40: 4053 | H40: Amana Toyota | I40: 4094
A41: Trust Toyota | E41: Harsha Toyota | F41: 4023 | H41: Lanson Toyota | I41: 4016
A42: United Toyota | E42: Galaxy Toyota | F42: 3988 | H42: Harsha Toyota | I42: 3935
A43: Kaizen Toyota | E43: Amana Toyota | F43: 3964 | H43: Anamallais Toyota | I43: 3021
...
